fill ~-49 ~-3 ~-49 ~-39 ~-1 ~-39 stone_bricks
fill ~-49 ~ ~-49 ~-39 ~24 ~-39 stone_bricks
fill ~-48 ~ ~-48 ~-40 ~23 ~-40 air
fill ~-49 ~ ~-49 ~-39 ~1 ~-39 cobblestone
fill ~-48 ~ ~-48 ~-40 ~1 ~-40 air
fill ~-48 ~9 ~-48 ~-40 ~9 ~-40 dark_oak_planks
fill ~-48 ~18 ~-48 ~-40 ~18 ~-40 dark_oak_planks
setblock ~-48 ~ ~-44 ladder[facing=east]
setblock ~-48 ~1 ~-44 ladder[facing=east]
setblock ~-48 ~2 ~-44 ladder[facing=east]
setblock ~-48 ~3 ~-44 ladder[facing=east]
setblock ~-48 ~4 ~-44 ladder[facing=east]
setblock ~-48 ~5 ~-44 ladder[facing=east]
setblock ~-48 ~6 ~-44 ladder[facing=east]
setblock ~-48 ~7 ~-44 ladder[facing=east]
setblock ~-48 ~8 ~-44 ladder[facing=east]
setblock ~-48 ~9 ~-44 ladder[facing=east]
setblock ~-48 ~10 ~-44 ladder[facing=east]
setblock ~-48 ~11 ~-44 ladder[facing=east]
setblock ~-48 ~12 ~-44 ladder[facing=east]
setblock ~-48 ~13 ~-44 ladder[facing=east]
setblock ~-48 ~14 ~-44 ladder[facing=east]
setblock ~-48 ~15 ~-44 ladder[facing=east]
setblock ~-48 ~16 ~-44 ladder[facing=east]
setblock ~-48 ~17 ~-44 ladder[facing=east]
setblock ~-48 ~18 ~-44 ladder[facing=east]
setblock ~-48 ~19 ~-44 ladder[facing=east]
setblock ~-48 ~20 ~-44 ladder[facing=east]
setblock ~-48 ~21 ~-44 ladder[facing=east]
setblock ~-48 ~22 ~-44 ladder[facing=east]
setblock ~-48 ~23 ~-44 ladder[facing=east]
setblock ~-48 ~24 ~-44 ladder[facing=east]
setblock ~-40 ~ ~-40 lantern[hanging=false]
setblock ~-40 ~10 ~-40 lantern[hanging=false]
setblock ~-40 ~19 ~-40 lantern[hanging=false]
fill ~-44 ~10 ~-39 ~-42 ~11 ~-39 air
fill ~-39 ~10 ~-44 ~-39 ~11 ~-42 air
fill ~-41 ~ ~-39 ~-41 ~1 ~-39 air
fill ~-44 ~5 ~-49 ~-44 ~6 ~-49 iron_bars
fill ~-49 ~5 ~-44 ~-49 ~6 ~-44 iron_bars
fill ~-44 ~14 ~-49 ~-44 ~15 ~-49 iron_bars
fill ~-49 ~14 ~-44 ~-49 ~15 ~-44 iron_bars
fill ~-49 ~25 ~-49 ~-39 ~25 ~-49 stone_bricks
fill ~-49 ~25 ~-39 ~-39 ~25 ~-39 stone_bricks
fill ~-49 ~25 ~-49 ~-49 ~25 ~-39 stone_bricks
fill ~-39 ~25 ~-49 ~-39 ~25 ~-39 stone_bricks
setblock ~-49 ~26 ~-49 stone_bricks
setblock ~-49 ~26 ~-39 stone_bricks
setblock ~-47 ~26 ~-49 stone_bricks
setblock ~-47 ~26 ~-39 stone_bricks
setblock ~-45 ~26 ~-49 stone_bricks
setblock ~-45 ~26 ~-39 stone_bricks
setblock ~-43 ~26 ~-49 stone_bricks
setblock ~-43 ~26 ~-39 stone_bricks
setblock ~-41 ~26 ~-49 stone_bricks
setblock ~-41 ~26 ~-39 stone_bricks
setblock ~-39 ~26 ~-49 stone_bricks
setblock ~-39 ~26 ~-39 stone_bricks
setblock ~-49 ~26 ~-49 stone_bricks
setblock ~-39 ~26 ~-49 stone_bricks
setblock ~-49 ~26 ~-47 stone_bricks
setblock ~-39 ~26 ~-47 stone_bricks
setblock ~-49 ~26 ~-45 stone_bricks
setblock ~-39 ~26 ~-45 stone_bricks
setblock ~-49 ~26 ~-43 stone_bricks
setblock ~-39 ~26 ~-43 stone_bricks
setblock ~-49 ~26 ~-41 stone_bricks
setblock ~-39 ~26 ~-41 stone_bricks
setblock ~-49 ~26 ~-39 stone_bricks
setblock ~-39 ~26 ~-39 stone_bricks
fill ~-44 ~25 ~-44 ~-44 ~29 ~-44 dark_oak_fence
setblock ~-44 ~30 ~-44 red_banner[rotation=0]
fill ~-49 ~-3 ~39 ~-39 ~-1 ~49 stone_bricks
fill ~-49 ~ ~39 ~-39 ~24 ~49 stone_bricks
fill ~-48 ~ ~40 ~-40 ~23 ~48 air
fill ~-49 ~ ~39 ~-39 ~1 ~49 cobblestone
fill ~-48 ~ ~40 ~-40 ~1 ~48 air
fill ~-48 ~9 ~40 ~-40 ~9 ~48 dark_oak_planks
fill ~-48 ~18 ~40 ~-40 ~18 ~48 dark_oak_planks
setblock ~-48 ~ ~44 ladder[facing=east]
setblock ~-48 ~1 ~44 ladder[facing=east]
setblock ~-48 ~2 ~44 ladder[facing=east]
setblock ~-48 ~3 ~44 ladder[facing=east]
setblock ~-48 ~4 ~44 ladder[facing=east]
setblock ~-48 ~5 ~44 ladder[facing=east]
setblock ~-48 ~6 ~44 ladder[facing=east]
setblock ~-48 ~7 ~44 ladder[facing=east]
setblock ~-48 ~8 ~44 ladder[facing=east]
setblock ~-48 ~9 ~44 ladder[facing=east]
setblock ~-48 ~10 ~44 ladder[facing=east]
setblock ~-48 ~11 ~44 ladder[facing=east]
setblock ~-48 ~12 ~44 ladder[facing=east]
setblock ~-48 ~13 ~44 ladder[facing=east]
setblock ~-48 ~14 ~44 ladder[facing=east]
setblock ~-48 ~15 ~44 ladder[facing=east]
setblock ~-48 ~16 ~44 ladder[facing=east]
setblock ~-48 ~17 ~44 ladder[facing=east]
setblock ~-48 ~18 ~44 ladder[facing=east]
setblock ~-48 ~19 ~44 ladder[facing=east]
setblock ~-48 ~20 ~44 ladder[facing=east]
setblock ~-48 ~21 ~44 ladder[facing=east]
setblock ~-48 ~22 ~44 ladder[facing=east]
setblock ~-48 ~23 ~44 ladder[facing=east]
setblock ~-48 ~24 ~44 ladder[facing=east]
setblock ~-40 ~ ~48 lantern[hanging=false]
setblock ~-40 ~10 ~48 lantern[hanging=false]
setblock ~-40 ~19 ~48 lantern[hanging=false]
fill ~-44 ~10 ~39 ~-42 ~11 ~39 air
fill ~-39 ~10 ~42 ~-39 ~11 ~44 air
fill ~-41 ~ ~39 ~-41 ~1 ~39 air
fill ~-44 ~5 ~49 ~-44 ~6 ~49 iron_bars
fill ~-49 ~5 ~44 ~-49 ~6 ~44 iron_bars
fill ~-44 ~14 ~49 ~-44 ~15 ~49 iron_bars
fill ~-49 ~14 ~44 ~-49 ~15 ~44 iron_bars
fill ~-49 ~25 ~39 ~-39 ~25 ~39 stone_bricks
fill ~-49 ~25 ~49 ~-39 ~25 ~49 stone_bricks
fill ~-49 ~25 ~39 ~-49 ~25 ~49 stone_bricks
fill ~-39 ~25 ~39 ~-39 ~25 ~49 stone_bricks
setblock ~-49 ~26 ~39 stone_bricks
setblock ~-49 ~26 ~49 stone_bricks
setblock ~-47 ~26 ~39 stone_bricks
setblock ~-47 ~26 ~49 stone_bricks
setblock ~-45 ~26 ~39 stone_bricks
setblock ~-45 ~26 ~49 stone_bricks
setblock ~-43 ~26 ~39 stone_bricks
setblock ~-43 ~26 ~49 stone_bricks
setblock ~-41 ~26 ~39 stone_bricks
setblock ~-41 ~26 ~49 stone_bricks
setblock ~-39 ~26 ~39 stone_bricks
setblock ~-39 ~26 ~49 stone_bricks
setblock ~-49 ~26 ~39 stone_bricks
setblock ~-39 ~26 ~39 stone_bricks
setblock ~-49 ~26 ~41 stone_bricks
setblock ~-39 ~26 ~41 stone_bricks
setblock ~-49 ~26 ~43 stone_bricks
setblock ~-39 ~26 ~43 stone_bricks
setblock ~-49 ~26 ~45 stone_bricks
setblock ~-39 ~26 ~45 stone_bricks
setblock ~-49 ~26 ~47 stone_bricks
setblock ~-39 ~26 ~47 stone_bricks
setblock ~-49 ~26 ~49 stone_bricks
setblock ~-39 ~26 ~49 stone_bricks
fill ~-44 ~25 ~44 ~-44 ~29 ~44 dark_oak_fence
setblock ~-44 ~30 ~44 red_banner[rotation=0]
fill ~39 ~-3 ~-49 ~49 ~-1 ~-39 stone_bricks
fill ~39 ~ ~-49 ~49 ~24 ~-39 stone_bricks
fill ~40 ~ ~-48 ~48 ~23 ~-40 air
fill ~39 ~ ~-49 ~49 ~1 ~-39 cobblestone
fill ~40 ~ ~-48 ~48 ~1 ~-40 air
fill ~40 ~9 ~-48 ~48 ~9 ~-40 dark_oak_planks
fill ~40 ~18 ~-48 ~48 ~18 ~-40 dark_oak_planks
setblock ~40 ~ ~-44 ladder[facing=east]
setblock ~40 ~1 ~-44 ladder[facing=east]
setblock ~40 ~2 ~-44 ladder[facing=east]
setblock ~40 ~3 ~-44 ladder[facing=east]
setblock ~40 ~4 ~-44 ladder[facing=east]
setblock ~40 ~5 ~-44 ladder[facing=east]
setblock ~40 ~6 ~-44 ladder[facing=east]
setblock ~40 ~7 ~-44 ladder[facing=east]
setblock ~40 ~8 ~-44 ladder[facing=east]
setblock ~40 ~9 ~-44 ladder[facing=east]
setblock ~40 ~10 ~-44 ladder[facing=east]
setblock ~40 ~11 ~-44 ladder[facing=east]
setblock ~40 ~12 ~-44 ladder[facing=east]
setblock ~40 ~13 ~-44 ladder[facing=east]
setblock ~40 ~14 ~-44 ladder[facing=east]
setblock ~40 ~15 ~-44 ladder[facing=east]
setblock ~40 ~16 ~-44 ladder[facing=east]
setblock ~40 ~17 ~-44 ladder[facing=east]
setblock ~40 ~18 ~-44 ladder[facing=east]
setblock ~40 ~19 ~-44 ladder[facing=east]
setblock ~40 ~20 ~-44 ladder[facing=east]
setblock ~40 ~21 ~-44 ladder[facing=east]
setblock ~40 ~22 ~-44 ladder[facing=east]
setblock ~40 ~23 ~-44 ladder[facing=east]
setblock ~40 ~24 ~-44 ladder[facing=east]
setblock ~48 ~ ~-40 lantern[hanging=false]
setblock ~48 ~10 ~-40 lantern[hanging=false]
setblock ~48 ~19 ~-40 lantern[hanging=false]
fill ~42 ~10 ~-39 ~44 ~11 ~-39 air
fill ~39 ~10 ~-44 ~39 ~11 ~-42 air
fill ~41 ~ ~-39 ~41 ~1 ~-39 air
fill ~44 ~5 ~-49 ~44 ~6 ~-49 iron_bars
fill ~49 ~5 ~-44 ~49 ~6 ~-44 iron_bars
fill ~44 ~14 ~-49 ~44 ~15 ~-49 iron_bars
fill ~49 ~14 ~-44 ~49 ~15 ~-44 iron_bars
fill ~39 ~25 ~-49 ~49 ~25 ~-49 stone_bricks
fill ~39 ~25 ~-39 ~49 ~25 ~-39 stone_bricks
fill ~39 ~25 ~-49 ~39 ~25 ~-39 stone_bricks
fill ~49 ~25 ~-49 ~49 ~25 ~-39 stone_bricks
setblock ~39 ~26 ~-49 stone_bricks
setblock ~39 ~26 ~-39 stone_bricks
setblock ~41 ~26 ~-49 stone_bricks
setblock ~41 ~26 ~-39 stone_bricks
setblock ~43 ~26 ~-49 stone_bricks
setblock ~43 ~26 ~-39 stone_bricks
setblock ~45 ~26 ~-49 stone_bricks
setblock ~45 ~26 ~-39 stone_bricks
setblock ~47 ~26 ~-49 stone_bricks
setblock ~47 ~26 ~-39 stone_bricks
setblock ~49 ~26 ~-49 stone_bricks
setblock ~49 ~26 ~-39 stone_bricks
setblock ~39 ~26 ~-49 stone_bricks
setblock ~49 ~26 ~-49 stone_bricks
setblock ~39 ~26 ~-47 stone_bricks
setblock ~49 ~26 ~-47 stone_bricks
setblock ~39 ~26 ~-45 stone_bricks
setblock ~49 ~26 ~-45 stone_bricks
setblock ~39 ~26 ~-43 stone_bricks
setblock ~49 ~26 ~-43 stone_bricks
setblock ~39 ~26 ~-41 stone_bricks
setblock ~49 ~26 ~-41 stone_bricks
setblock ~39 ~26 ~-39 stone_bricks
setblock ~49 ~26 ~-39 stone_bricks
fill ~44 ~25 ~-44 ~44 ~29 ~-44 dark_oak_fence
setblock ~44 ~30 ~-44 red_banner[rotation=0]
fill ~39 ~-3 ~39 ~49 ~-1 ~49 stone_bricks
fill ~39 ~ ~39 ~49 ~24 ~49 stone_bricks
fill ~40 ~ ~40 ~48 ~23 ~48 air
fill ~39 ~ ~39 ~49 ~1 ~49 cobblestone
fill ~40 ~ ~40 ~48 ~1 ~48 air
fill ~40 ~9 ~40 ~48 ~9 ~48 dark_oak_planks
fill ~40 ~18 ~40 ~48 ~18 ~48 dark_oak_planks
setblock ~40 ~ ~44 ladder[facing=east]
setblock ~40 ~1 ~44 ladder[facing=east]
setblock ~40 ~2 ~44 ladder[facing=east]
setblock ~40 ~3 ~44 ladder[facing=east]
setblock ~40 ~4 ~44 ladder[facing=east]
setblock ~40 ~5 ~44 ladder[facing=east]
setblock ~40 ~6 ~44 ladder[facing=east]
setblock ~40 ~7 ~44 ladder[facing=east]
setblock ~40 ~8 ~44 ladder[facing=east]
setblock ~40 ~9 ~44 ladder[facing=east]
setblock ~40 ~10 ~44 ladder[facing=east]
setblock ~40 ~11 ~44 ladder[facing=east]
setblock ~40 ~12 ~44 ladder[facing=east]
setblock ~40 ~13 ~44 ladder[facing=east]
setblock ~40 ~14 ~44 ladder[facing=east]
setblock ~40 ~15 ~44 ladder[facing=east]
setblock ~40 ~16 ~44 ladder[facing=east]
setblock ~40 ~17 ~44 ladder[facing=east]
setblock ~40 ~18 ~44 ladder[facing=east]
setblock ~40 ~19 ~44 ladder[facing=east]
setblock ~40 ~20 ~44 ladder[facing=east]
setblock ~40 ~21 ~44 ladder[facing=east]
setblock ~40 ~22 ~44 ladder[facing=east]
setblock ~40 ~23 ~44 ladder[facing=east]
setblock ~40 ~24 ~44 ladder[facing=east]
setblock ~48 ~ ~48 lantern[hanging=false]
setblock ~48 ~10 ~48 lantern[hanging=false]
setblock ~48 ~19 ~48 lantern[hanging=false]
fill ~42 ~10 ~39 ~44 ~11 ~39 air
fill ~39 ~10 ~42 ~39 ~11 ~44 air
fill ~41 ~ ~39 ~41 ~1 ~39 air
fill ~44 ~5 ~49 ~44 ~6 ~49 iron_bars
fill ~49 ~5 ~44 ~49 ~6 ~44 iron_bars
fill ~44 ~14 ~49 ~44 ~15 ~49 iron_bars
fill ~49 ~14 ~44 ~49 ~15 ~44 iron_bars
fill ~39 ~25 ~39 ~49 ~25 ~39 stone_bricks
fill ~39 ~25 ~49 ~49 ~25 ~49 stone_bricks
fill ~39 ~25 ~39 ~39 ~25 ~49 stone_bricks
fill ~49 ~25 ~39 ~49 ~25 ~49 stone_bricks
setblock ~39 ~26 ~39 stone_bricks
setblock ~39 ~26 ~49 stone_bricks
setblock ~41 ~26 ~39 stone_bricks
setblock ~41 ~26 ~49 stone_bricks
setblock ~43 ~26 ~39 stone_bricks
setblock ~43 ~26 ~49 stone_bricks
setblock ~45 ~26 ~39 stone_bricks
setblock ~45 ~26 ~49 stone_bricks
setblock ~47 ~26 ~39 stone_bricks
setblock ~47 ~26 ~49 stone_bricks
setblock ~49 ~26 ~39 stone_bricks
setblock ~49 ~26 ~49 stone_bricks
setblock ~39 ~26 ~39 stone_bricks
setblock ~49 ~26 ~39 stone_bricks
setblock ~39 ~26 ~41 stone_bricks
setblock ~49 ~26 ~41 stone_bricks
setblock ~39 ~26 ~43 stone_bricks
setblock ~49 ~26 ~43 stone_bricks
setblock ~39 ~26 ~45 stone_bricks
setblock ~49 ~26 ~45 stone_bricks
setblock ~39 ~26 ~47 stone_bricks
setblock ~49 ~26 ~47 stone_bricks
setblock ~39 ~26 ~49 stone_bricks
setblock ~49 ~26 ~49 stone_bricks
fill ~44 ~25 ~44 ~44 ~29 ~44 dark_oak_fence
setblock ~44 ~30 ~44 red_banner[rotation=0]
fill ~-3 ~-3 ~-47 ~3 ~-1 ~-41 stone_bricks
fill ~-3 ~ ~-47 ~3 ~15 ~-41 stone_bricks
fill ~-2 ~ ~-46 ~2 ~14 ~-42 air
fill ~-3 ~ ~-47 ~3 ~1 ~-41 cobblestone
fill ~-2 ~ ~-46 ~2 ~1 ~-42 air
fill ~-2 ~9 ~-46 ~2 ~9 ~-42 dark_oak_planks
setblock ~-2 ~ ~-44 ladder[facing=east]
setblock ~-2 ~1 ~-44 ladder[facing=east]
setblock ~-2 ~2 ~-44 ladder[facing=east]
setblock ~-2 ~3 ~-44 ladder[facing=east]
setblock ~-2 ~4 ~-44 ladder[facing=east]
setblock ~-2 ~5 ~-44 ladder[facing=east]
setblock ~-2 ~6 ~-44 ladder[facing=east]
setblock ~-2 ~7 ~-44 ladder[facing=east]
setblock ~-2 ~8 ~-44 ladder[facing=east]
setblock ~-2 ~9 ~-44 ladder[facing=east]
setblock ~-2 ~10 ~-44 ladder[facing=east]
setblock ~-2 ~11 ~-44 ladder[facing=east]
setblock ~-2 ~12 ~-44 ladder[facing=east]
setblock ~-2 ~13 ~-44 ladder[facing=east]
setblock ~-2 ~14 ~-44 ladder[facing=east]
setblock ~-2 ~15 ~-44 ladder[facing=east]
setblock ~2 ~ ~-42 lantern[hanging=false]
setblock ~2 ~10 ~-42 lantern[hanging=false]
fill ~-3 ~10 ~-44 ~-3 ~11 ~-42 air
fill ~3 ~10 ~-44 ~3 ~11 ~-42 air
fill ~1 ~ ~-41 ~1 ~1 ~-41 air
fill ~ ~5 ~-47 ~ ~6 ~-47 iron_bars
fill ~ ~12 ~-47 ~ ~13 ~-47 iron_bars
fill ~-3 ~16 ~-47 ~3 ~16 ~-47 stone_bricks
fill ~-3 ~16 ~-41 ~3 ~16 ~-41 stone_bricks
fill ~-3 ~16 ~-47 ~-3 ~16 ~-41 stone_bricks
fill ~3 ~16 ~-47 ~3 ~16 ~-41 stone_bricks
setblock ~-3 ~17 ~-47 stone_bricks
setblock ~-3 ~17 ~-41 stone_bricks
setblock ~-1 ~17 ~-47 stone_bricks
setblock ~-1 ~17 ~-41 stone_bricks
setblock ~1 ~17 ~-47 stone_bricks
setblock ~1 ~17 ~-41 stone_bricks
setblock ~3 ~17 ~-47 stone_bricks
setblock ~3 ~17 ~-41 stone_bricks
setblock ~-3 ~17 ~-47 stone_bricks
setblock ~3 ~17 ~-47 stone_bricks
setblock ~-3 ~17 ~-45 stone_bricks
setblock ~3 ~17 ~-45 stone_bricks
setblock ~-3 ~17 ~-43 stone_bricks
setblock ~3 ~17 ~-43 stone_bricks
setblock ~-3 ~17 ~-41 stone_bricks
setblock ~3 ~17 ~-41 stone_bricks
fill ~ ~16 ~-44 ~ ~20 ~-44 dark_oak_fence
setblock ~ ~21 ~-44 red_banner[rotation=0]
fill ~-47 ~-3 ~-3 ~-41 ~-1 ~3 stone_bricks
fill ~-47 ~ ~-3 ~-41 ~15 ~3 stone_bricks
fill ~-46 ~ ~-2 ~-42 ~14 ~2 air
fill ~-47 ~ ~-3 ~-41 ~1 ~3 cobblestone
fill ~-46 ~ ~-2 ~-42 ~1 ~2 air
fill ~-46 ~9 ~-2 ~-42 ~9 ~2 dark_oak_planks
setblock ~-46 ~ ~ ladder[facing=east]
setblock ~-46 ~1 ~ ladder[facing=east]
setblock ~-46 ~2 ~ ladder[facing=east]
setblock ~-46 ~3 ~ ladder[facing=east]
setblock ~-46 ~4 ~ ladder[facing=east]
setblock ~-46 ~5 ~ ladder[facing=east]
setblock ~-46 ~6 ~ ladder[facing=east]
setblock ~-46 ~7 ~ ladder[facing=east]
setblock ~-46 ~8 ~ ladder[facing=east]
setblock ~-46 ~9 ~ ladder[facing=east]
setblock ~-46 ~10 ~ ladder[facing=east]
setblock ~-46 ~11 ~ ladder[facing=east]
setblock ~-46 ~12 ~ ladder[facing=east]
setblock ~-46 ~13 ~ ladder[facing=east]
setblock ~-46 ~14 ~ ladder[facing=east]
setblock ~-46 ~15 ~ ladder[facing=east]
setblock ~-42 ~ ~2 lantern[hanging=false]
setblock ~-42 ~10 ~2 lantern[hanging=false]
fill ~-44 ~10 ~-3 ~-42 ~11 ~-3 air
fill ~-44 ~10 ~3 ~-42 ~11 ~3 air
fill ~-41 ~ ~1 ~-41 ~1 ~1 air
fill ~-47 ~5 ~ ~-47 ~6 ~ iron_bars
fill ~-47 ~12 ~ ~-47 ~13 ~ iron_bars
fill ~-47 ~16 ~-3 ~-41 ~16 ~-3 stone_bricks
fill ~-47 ~16 ~3 ~-41 ~16 ~3 stone_bricks
fill ~-47 ~16 ~-3 ~-47 ~16 ~3 stone_bricks
fill ~-41 ~16 ~-3 ~-41 ~16 ~3 stone_bricks
setblock ~-47 ~17 ~-3 stone_bricks
setblock ~-47 ~17 ~3 stone_bricks
setblock ~-45 ~17 ~-3 stone_bricks
setblock ~-45 ~17 ~3 stone_bricks
setblock ~-43 ~17 ~-3 stone_bricks
setblock ~-43 ~17 ~3 stone_bricks
setblock ~-41 ~17 ~-3 stone_bricks
setblock ~-41 ~17 ~3 stone_bricks
setblock ~-47 ~17 ~-3 stone_bricks
setblock ~-41 ~17 ~-3 stone_bricks
setblock ~-47 ~17 ~-1 stone_bricks
setblock ~-41 ~17 ~-1 stone_bricks
setblock ~-47 ~17 ~1 stone_bricks
setblock ~-41 ~17 ~1 stone_bricks
setblock ~-47 ~17 ~3 stone_bricks
setblock ~-41 ~17 ~3 stone_bricks
fill ~-44 ~16 ~ ~-44 ~20 ~ dark_oak_fence
setblock ~-44 ~21 ~ red_banner[rotation=0]
fill ~41 ~-3 ~-3 ~47 ~-1 ~3 stone_bricks
fill ~41 ~ ~-3 ~47 ~15 ~3 stone_bricks
fill ~42 ~ ~-2 ~46 ~14 ~2 air
fill ~41 ~ ~-3 ~47 ~1 ~3 cobblestone
fill ~42 ~ ~-2 ~46 ~1 ~2 air
fill ~42 ~9 ~-2 ~46 ~9 ~2 dark_oak_planks
setblock ~42 ~ ~ ladder[facing=east]
setblock ~42 ~1 ~ ladder[facing=east]
setblock ~42 ~2 ~ ladder[facing=east]
setblock ~42 ~3 ~ ladder[facing=east]
setblock ~42 ~4 ~ ladder[facing=east]
setblock ~42 ~5 ~ ladder[facing=east]
setblock ~42 ~6 ~ ladder[facing=east]
setblock ~42 ~7 ~ ladder[facing=east]
setblock ~42 ~8 ~ ladder[facing=east]
setblock ~42 ~9 ~ ladder[facing=east]
setblock ~42 ~10 ~ ladder[facing=east]
setblock ~42 ~11 ~ ladder[facing=east]
setblock ~42 ~12 ~ ladder[facing=east]
setblock ~42 ~13 ~ ladder[facing=east]
setblock ~42 ~14 ~ ladder[facing=east]
setblock ~42 ~15 ~ ladder[facing=east]
setblock ~46 ~ ~2 lantern[hanging=false]
setblock ~46 ~10 ~2 lantern[hanging=false]
fill ~42 ~10 ~-3 ~44 ~11 ~-3 air
fill ~42 ~10 ~3 ~44 ~11 ~3 air
fill ~41 ~ ~1 ~41 ~1 ~1 air
fill ~47 ~5 ~ ~47 ~6 ~ iron_bars
fill ~47 ~12 ~ ~47 ~13 ~ iron_bars
fill ~41 ~16 ~-3 ~47 ~16 ~-3 stone_bricks
fill ~41 ~16 ~3 ~47 ~16 ~3 stone_bricks
fill ~41 ~16 ~-3 ~41 ~16 ~3 stone_bricks
fill ~47 ~16 ~-3 ~47 ~16 ~3 stone_bricks
setblock ~41 ~17 ~-3 stone_bricks
setblock ~41 ~17 ~3 stone_bricks
setblock ~43 ~17 ~-3 stone_bricks
setblock ~43 ~17 ~3 stone_bricks
setblock ~45 ~17 ~-3 stone_bricks
setblock ~45 ~17 ~3 stone_bricks
setblock ~47 ~17 ~-3 stone_bricks
setblock ~47 ~17 ~3 stone_bricks
setblock ~41 ~17 ~-3 stone_bricks
setblock ~47 ~17 ~-3 stone_bricks
setblock ~41 ~17 ~-1 stone_bricks
setblock ~47 ~17 ~-1 stone_bricks
setblock ~41 ~17 ~1 stone_bricks
setblock ~47 ~17 ~1 stone_bricks
setblock ~41 ~17 ~3 stone_bricks
setblock ~47 ~17 ~3 stone_bricks
fill ~44 ~16 ~ ~44 ~20 ~ dark_oak_fence
setblock ~44 ~21 ~ red_banner[rotation=0]
