fill ~-13 ~-3 ~36 ~13 ~-1 ~46 stone_bricks
fill ~-13 ~ ~36 ~13 ~1 ~46 cobblestone
fill ~-13 ~2 ~36 ~13 ~16 ~46 stone_bricks
fill ~-13 ~17 ~36 ~13 ~17 ~46 polished_andesite
fill ~-13 ~ ~36 ~-13 ~17 ~36 polished_andesite
fill ~-13 ~ ~46 ~-13 ~17 ~46 polished_andesite
fill ~13 ~ ~36 ~13 ~17 ~36 polished_andesite
fill ~13 ~ ~46 ~13 ~17 ~46 polished_andesite
fill ~-4 ~ ~36 ~4 ~9 ~46 air
fill ~-4 ~-1 ~36 ~4 ~-1 ~46 stone_bricks
fill ~-5 ~ ~46 ~-5 ~9 ~46 chiseled_stone_bricks
fill ~5 ~ ~46 ~5 ~9 ~46 chiseled_stone_bricks
fill ~-5 ~10 ~46 ~5 ~10 ~46 chiseled_stone_bricks
fill ~-4 ~6 ~45 ~4 ~9 ~45 iron_bars
setblock ~-3 ~9 ~38 lantern[hanging=true]
setblock ~3 ~9 ~38 lantern[hanging=true]
setblock ~-3 ~9 ~42 lantern[hanging=true]
setblock ~3 ~9 ~42 lantern[hanging=true]
fill ~-10 ~12 ~46 ~-10 ~13 ~46 iron_bars
fill ~-7 ~12 ~46 ~-7 ~13 ~46 iron_bars
fill ~7 ~12 ~46 ~7 ~13 ~46 iron_bars
fill ~10 ~12 ~46 ~10 ~13 ~46 iron_bars
setblock ~-8 ~6 ~47 red_wall_banner[facing=south]
setblock ~8 ~6 ~47 red_wall_banner[facing=south]
setblock ~-11 ~6 ~47 black_wall_banner[facing=south]
setblock ~11 ~6 ~47 black_wall_banner[facing=south]
setblock ~-11 ~ ~35 ladder[facing=north]
setblock ~-11 ~1 ~35 ladder[facing=north]
setblock ~-11 ~2 ~35 ladder[facing=north]
setblock ~-11 ~3 ~35 ladder[facing=north]
setblock ~-11 ~4 ~35 ladder[facing=north]
setblock ~-11 ~5 ~35 ladder[facing=north]
setblock ~-11 ~6 ~35 ladder[facing=north]
setblock ~-11 ~7 ~35 ladder[facing=north]
setblock ~-11 ~8 ~35 ladder[facing=north]
setblock ~-11 ~9 ~35 ladder[facing=north]
setblock ~-11 ~10 ~35 ladder[facing=north]
setblock ~-11 ~11 ~35 ladder[facing=north]
setblock ~-11 ~12 ~35 ladder[facing=north]
setblock ~-11 ~13 ~35 ladder[facing=north]
setblock ~-11 ~14 ~35 ladder[facing=north]
setblock ~-11 ~15 ~35 ladder[facing=north]
setblock ~-11 ~16 ~35 ladder[facing=north]
setblock ~-11 ~17 ~35 ladder[facing=north]
setblock ~11 ~ ~35 ladder[facing=north]
setblock ~11 ~1 ~35 ladder[facing=north]
setblock ~11 ~2 ~35 ladder[facing=north]
setblock ~11 ~3 ~35 ladder[facing=north]
setblock ~11 ~4 ~35 ladder[facing=north]
setblock ~11 ~5 ~35 ladder[facing=north]
setblock ~11 ~6 ~35 ladder[facing=north]
setblock ~11 ~7 ~35 ladder[facing=north]
setblock ~11 ~8 ~35 ladder[facing=north]
setblock ~11 ~9 ~35 ladder[facing=north]
setblock ~11 ~10 ~35 ladder[facing=north]
setblock ~11 ~11 ~35 ladder[facing=north]
setblock ~11 ~12 ~35 ladder[facing=north]
setblock ~11 ~13 ~35 ladder[facing=north]
setblock ~11 ~14 ~35 ladder[facing=north]
setblock ~11 ~15 ~35 ladder[facing=north]
setblock ~11 ~16 ~35 ladder[facing=north]
setblock ~11 ~17 ~35 ladder[facing=north]
fill ~-13 ~18 ~36 ~13 ~18 ~36 stone_bricks
fill ~-13 ~18 ~46 ~13 ~18 ~46 stone_bricks
fill ~-13 ~18 ~36 ~-13 ~18 ~46 stone_bricks
fill ~13 ~18 ~36 ~13 ~18 ~46 stone_bricks
setblock ~-13 ~19 ~36 stone_bricks
setblock ~-13 ~19 ~46 stone_bricks
setblock ~-11 ~19 ~36 stone_bricks
setblock ~-11 ~19 ~46 stone_bricks
setblock ~-9 ~19 ~36 stone_bricks
setblock ~-9 ~19 ~46 stone_bricks
setblock ~-7 ~19 ~36 stone_bricks
setblock ~-7 ~19 ~46 stone_bricks
setblock ~-5 ~19 ~36 stone_bricks
setblock ~-5 ~19 ~46 stone_bricks
setblock ~-3 ~19 ~36 stone_bricks
setblock ~-3 ~19 ~46 stone_bricks
setblock ~-1 ~19 ~36 stone_bricks
setblock ~-1 ~19 ~46 stone_bricks
setblock ~1 ~19 ~36 stone_bricks
setblock ~1 ~19 ~46 stone_bricks
setblock ~3 ~19 ~36 stone_bricks
setblock ~3 ~19 ~46 stone_bricks
setblock ~5 ~19 ~36 stone_bricks
setblock ~5 ~19 ~46 stone_bricks
setblock ~7 ~19 ~36 stone_bricks
setblock ~7 ~19 ~46 stone_bricks
setblock ~9 ~19 ~36 stone_bricks
setblock ~9 ~19 ~46 stone_bricks
setblock ~11 ~19 ~36 stone_bricks
setblock ~11 ~19 ~46 stone_bricks
setblock ~13 ~19 ~36 stone_bricks
setblock ~13 ~19 ~46 stone_bricks
setblock ~-13 ~19 ~36 stone_bricks
setblock ~13 ~19 ~36 stone_bricks
setblock ~-13 ~19 ~38 stone_bricks
setblock ~13 ~19 ~38 stone_bricks
setblock ~-13 ~19 ~40 stone_bricks
setblock ~13 ~19 ~40 stone_bricks
setblock ~-13 ~19 ~42 stone_bricks
setblock ~13 ~19 ~42 stone_bricks
setblock ~-13 ~19 ~44 stone_bricks
setblock ~13 ~19 ~44 stone_bricks
setblock ~-13 ~19 ~46 stone_bricks
setblock ~13 ~19 ~46 stone_bricks
fill ~-11 ~18 ~36 ~-11 ~19 ~36 air
fill ~11 ~18 ~36 ~11 ~19 ~36 air
fill ~-13 ~18 ~41 ~-13 ~22 ~41 dark_oak_fence
setblock ~-13 ~23 ~41 red_banner[rotation=0]
fill ~13 ~18 ~41 ~13 ~22 ~41 dark_oak_fence
setblock ~13 ~23 ~41 red_banner[rotation=0]
fill ~-3 ~-1 ~47 ~3 ~-1 ~56 stone_bricks
fill ~-2 ~-1 ~47 ~2 ~-1 ~56 cobblestone
fill ~-4 ~ ~48 ~-4 ~1 ~48 stone_brick_wall
setblock ~-4 ~2 ~48 lantern[hanging=false]
fill ~4 ~ ~48 ~4 ~1 ~48 stone_brick_wall
setblock ~4 ~2 ~48 lantern[hanging=false]
fill ~-4 ~ ~54 ~-4 ~1 ~54 stone_brick_wall
setblock ~-4 ~2 ~54 lantern[hanging=false]
fill ~4 ~ ~54 ~4 ~1 ~54 stone_brick_wall
setblock ~4 ~2 ~54 lantern[hanging=false]
