fill ~-18 ~-3 ~-24 ~18 ~-1 ~12 polished_blackstone_bricks
fill ~-18 ~ ~-24 ~18 ~1 ~12 deepslate_bricks
fill ~-18 ~2 ~-24 ~18 ~17 ~12 stone_bricks
fill ~-18 ~18 ~-24 ~18 ~19 ~12 polished_andesite
fill ~-18 ~20 ~-24 ~18 ~20 ~-24 stone_bricks
fill ~-18 ~20 ~12 ~18 ~20 ~12 stone_bricks
fill ~-18 ~20 ~-24 ~-18 ~20 ~12 stone_bricks
fill ~18 ~20 ~-24 ~18 ~20 ~12 stone_bricks
setblock ~-18 ~21 ~-24 stone_bricks
setblock ~-18 ~21 ~12 stone_bricks
setblock ~-16 ~21 ~-24 stone_bricks
setblock ~-16 ~21 ~12 stone_bricks
setblock ~-14 ~21 ~-24 stone_bricks
setblock ~-14 ~21 ~12 stone_bricks
setblock ~-12 ~21 ~-24 stone_bricks
setblock ~-12 ~21 ~12 stone_bricks
setblock ~-10 ~21 ~-24 stone_bricks
setblock ~-10 ~21 ~12 stone_bricks
setblock ~-8 ~21 ~-24 stone_bricks
setblock ~-8 ~21 ~12 stone_bricks
setblock ~-6 ~21 ~-24 stone_bricks
setblock ~-6 ~21 ~12 stone_bricks
setblock ~-4 ~21 ~-24 stone_bricks
setblock ~-4 ~21 ~12 stone_bricks
setblock ~-2 ~21 ~-24 stone_bricks
setblock ~-2 ~21 ~12 stone_bricks
setblock ~ ~21 ~-24 stone_bricks
setblock ~ ~21 ~12 stone_bricks
setblock ~2 ~21 ~-24 stone_bricks
setblock ~2 ~21 ~12 stone_bricks
setblock ~4 ~21 ~-24 stone_bricks
setblock ~4 ~21 ~12 stone_bricks
setblock ~6 ~21 ~-24 stone_bricks
setblock ~6 ~21 ~12 stone_bricks
setblock ~8 ~21 ~-24 stone_bricks
setblock ~8 ~21 ~12 stone_bricks
setblock ~10 ~21 ~-24 stone_bricks
setblock ~10 ~21 ~12 stone_bricks
setblock ~12 ~21 ~-24 stone_bricks
setblock ~12 ~21 ~12 stone_bricks
setblock ~14 ~21 ~-24 stone_bricks
setblock ~14 ~21 ~12 stone_bricks
setblock ~16 ~21 ~-24 stone_bricks
setblock ~16 ~21 ~12 stone_bricks
setblock ~18 ~21 ~-24 stone_bricks
setblock ~18 ~21 ~12 stone_bricks
setblock ~-18 ~21 ~-24 stone_bricks
setblock ~18 ~21 ~-24 stone_bricks
setblock ~-18 ~21 ~-22 stone_bricks
setblock ~18 ~21 ~-22 stone_bricks
setblock ~-18 ~21 ~-20 stone_bricks
setblock ~18 ~21 ~-20 stone_bricks
setblock ~-18 ~21 ~-18 stone_bricks
setblock ~18 ~21 ~-18 stone_bricks
setblock ~-18 ~21 ~-16 stone_bricks
setblock ~18 ~21 ~-16 stone_bricks
setblock ~-18 ~21 ~-14 stone_bricks
setblock ~18 ~21 ~-14 stone_bricks
setblock ~-18 ~21 ~-12 stone_bricks
setblock ~18 ~21 ~-12 stone_bricks
setblock ~-18 ~21 ~-10 stone_bricks
setblock ~18 ~21 ~-10 stone_bricks
setblock ~-18 ~21 ~-8 stone_bricks
setblock ~18 ~21 ~-8 stone_bricks
setblock ~-18 ~21 ~-6 stone_bricks
setblock ~18 ~21 ~-6 stone_bricks
setblock ~-18 ~21 ~-4 stone_bricks
setblock ~18 ~21 ~-4 stone_bricks
setblock ~-18 ~21 ~-2 stone_bricks
setblock ~18 ~21 ~-2 stone_bricks
setblock ~-18 ~21 ~ stone_bricks
setblock ~18 ~21 ~ stone_bricks
setblock ~-18 ~21 ~2 stone_bricks
setblock ~18 ~21 ~2 stone_bricks
setblock ~-18 ~21 ~4 stone_bricks
setblock ~18 ~21 ~4 stone_bricks
setblock ~-18 ~21 ~6 stone_bricks
setblock ~18 ~21 ~6 stone_bricks
setblock ~-18 ~21 ~8 stone_bricks
setblock ~18 ~21 ~8 stone_bricks
setblock ~-18 ~21 ~10 stone_bricks
setblock ~18 ~21 ~10 stone_bricks
setblock ~-18 ~21 ~12 stone_bricks
setblock ~18 ~21 ~12 stone_bricks
fill ~14 ~ ~-28 ~22 ~30 ~-20 stone_bricks
fill ~15 ~ ~-27 ~21 ~29 ~-21 air
fill ~14 ~ ~-28 ~22 ~1 ~-20 cobblestone
fill ~15 ~ ~-27 ~21 ~1 ~-21 air
fill ~15 ~19 ~-27 ~21 ~19 ~-21 dark_oak_planks
setblock ~15 ~ ~-24 ladder[facing=east]
setblock ~15 ~1 ~-24 ladder[facing=east]
setblock ~15 ~2 ~-24 ladder[facing=east]
setblock ~15 ~3 ~-24 ladder[facing=east]
setblock ~15 ~4 ~-24 ladder[facing=east]
setblock ~15 ~5 ~-24 ladder[facing=east]
setblock ~15 ~6 ~-24 ladder[facing=east]
setblock ~15 ~7 ~-24 ladder[facing=east]
setblock ~15 ~8 ~-24 ladder[facing=east]
setblock ~15 ~9 ~-24 ladder[facing=east]
setblock ~15 ~10 ~-24 ladder[facing=east]
setblock ~15 ~11 ~-24 ladder[facing=east]
setblock ~15 ~12 ~-24 ladder[facing=east]
setblock ~15 ~13 ~-24 ladder[facing=east]
setblock ~15 ~14 ~-24 ladder[facing=east]
setblock ~15 ~15 ~-24 ladder[facing=east]
setblock ~15 ~16 ~-24 ladder[facing=east]
setblock ~15 ~17 ~-24 ladder[facing=east]
setblock ~15 ~18 ~-24 ladder[facing=east]
setblock ~15 ~19 ~-24 ladder[facing=east]
setblock ~15 ~20 ~-24 ladder[facing=east]
setblock ~15 ~21 ~-24 ladder[facing=east]
setblock ~15 ~22 ~-24 ladder[facing=east]
setblock ~15 ~23 ~-24 ladder[facing=east]
setblock ~15 ~24 ~-24 ladder[facing=east]
setblock ~15 ~25 ~-24 ladder[facing=east]
setblock ~15 ~26 ~-24 ladder[facing=east]
setblock ~15 ~27 ~-24 ladder[facing=east]
setblock ~15 ~28 ~-24 ladder[facing=east]
setblock ~15 ~29 ~-24 ladder[facing=east]
setblock ~15 ~30 ~-24 ladder[facing=east]
setblock ~21 ~ ~-21 lantern[hanging=false]
setblock ~21 ~20 ~-21 lantern[hanging=false]
fill ~14 ~20 ~-22 ~14 ~21 ~-22 air
fill ~16 ~20 ~-20 ~16 ~21 ~-20 air
fill ~22 ~24 ~-24 ~22 ~25 ~-24 iron_bars
fill ~18 ~24 ~-28 ~18 ~25 ~-28 iron_bars
fill ~14 ~31 ~-28 ~22 ~31 ~-28 stone_bricks
fill ~14 ~31 ~-20 ~22 ~31 ~-20 stone_bricks
fill ~14 ~31 ~-28 ~14 ~31 ~-20 stone_bricks
fill ~22 ~31 ~-28 ~22 ~31 ~-20 stone_bricks
setblock ~14 ~32 ~-28 stone_bricks
setblock ~14 ~32 ~-20 stone_bricks
setblock ~16 ~32 ~-28 stone_bricks
setblock ~16 ~32 ~-20 stone_bricks
setblock ~18 ~32 ~-28 stone_bricks
setblock ~18 ~32 ~-20 stone_bricks
setblock ~20 ~32 ~-28 stone_bricks
setblock ~20 ~32 ~-20 stone_bricks
setblock ~22 ~32 ~-28 stone_bricks
setblock ~22 ~32 ~-20 stone_bricks
setblock ~14 ~32 ~-28 stone_bricks
setblock ~22 ~32 ~-28 stone_bricks
setblock ~14 ~32 ~-26 stone_bricks
setblock ~22 ~32 ~-26 stone_bricks
setblock ~14 ~32 ~-24 stone_bricks
setblock ~22 ~32 ~-24 stone_bricks
setblock ~14 ~32 ~-22 stone_bricks
setblock ~22 ~32 ~-22 stone_bricks
setblock ~14 ~32 ~-20 stone_bricks
setblock ~22 ~32 ~-20 stone_bricks
fill ~18 ~31 ~-24 ~18 ~35 ~-24 dark_oak_fence
setblock ~18 ~36 ~-24 red_banner[rotation=0]
fill ~-22 ~ ~-28 ~-14 ~30 ~-20 stone_bricks
fill ~-21 ~ ~-27 ~-15 ~29 ~-21 air
fill ~-22 ~ ~-28 ~-14 ~1 ~-20 cobblestone
fill ~-21 ~ ~-27 ~-15 ~1 ~-21 air
fill ~-21 ~19 ~-27 ~-15 ~19 ~-21 dark_oak_planks
setblock ~-21 ~ ~-24 ladder[facing=east]
setblock ~-21 ~1 ~-24 ladder[facing=east]
setblock ~-21 ~2 ~-24 ladder[facing=east]
setblock ~-21 ~3 ~-24 ladder[facing=east]
setblock ~-21 ~4 ~-24 ladder[facing=east]
setblock ~-21 ~5 ~-24 ladder[facing=east]
setblock ~-21 ~6 ~-24 ladder[facing=east]
setblock ~-21 ~7 ~-24 ladder[facing=east]
setblock ~-21 ~8 ~-24 ladder[facing=east]
setblock ~-21 ~9 ~-24 ladder[facing=east]
setblock ~-21 ~10 ~-24 ladder[facing=east]
setblock ~-21 ~11 ~-24 ladder[facing=east]
setblock ~-21 ~12 ~-24 ladder[facing=east]
setblock ~-21 ~13 ~-24 ladder[facing=east]
setblock ~-21 ~14 ~-24 ladder[facing=east]
setblock ~-21 ~15 ~-24 ladder[facing=east]
setblock ~-21 ~16 ~-24 ladder[facing=east]
setblock ~-21 ~17 ~-24 ladder[facing=east]
setblock ~-21 ~18 ~-24 ladder[facing=east]
setblock ~-21 ~19 ~-24 ladder[facing=east]
setblock ~-21 ~20 ~-24 ladder[facing=east]
setblock ~-21 ~21 ~-24 ladder[facing=east]
setblock ~-21 ~22 ~-24 ladder[facing=east]
setblock ~-21 ~23 ~-24 ladder[facing=east]
setblock ~-21 ~24 ~-24 ladder[facing=east]
setblock ~-21 ~25 ~-24 ladder[facing=east]
setblock ~-21 ~26 ~-24 ladder[facing=east]
setblock ~-21 ~27 ~-24 ladder[facing=east]
setblock ~-21 ~28 ~-24 ladder[facing=east]
setblock ~-21 ~29 ~-24 ladder[facing=east]
setblock ~-21 ~30 ~-24 ladder[facing=east]
setblock ~-15 ~ ~-21 lantern[hanging=false]
setblock ~-15 ~20 ~-21 lantern[hanging=false]
fill ~-14 ~20 ~-22 ~-14 ~21 ~-22 air
fill ~-16 ~20 ~-20 ~-16 ~21 ~-20 air
fill ~-22 ~24 ~-24 ~-22 ~25 ~-24 iron_bars
fill ~-18 ~24 ~-28 ~-18 ~25 ~-28 iron_bars
fill ~-22 ~31 ~-28 ~-14 ~31 ~-28 stone_bricks
fill ~-22 ~31 ~-20 ~-14 ~31 ~-20 stone_bricks
fill ~-22 ~31 ~-28 ~-22 ~31 ~-20 stone_bricks
fill ~-14 ~31 ~-28 ~-14 ~31 ~-20 stone_bricks
setblock ~-22 ~32 ~-28 stone_bricks
setblock ~-22 ~32 ~-20 stone_bricks
setblock ~-20 ~32 ~-28 stone_bricks
setblock ~-20 ~32 ~-20 stone_bricks
setblock ~-18 ~32 ~-28 stone_bricks
setblock ~-18 ~32 ~-20 stone_bricks
setblock ~-16 ~32 ~-28 stone_bricks
setblock ~-16 ~32 ~-20 stone_bricks
setblock ~-14 ~32 ~-28 stone_bricks
setblock ~-14 ~32 ~-20 stone_bricks
setblock ~-22 ~32 ~-28 stone_bricks
setblock ~-14 ~32 ~-28 stone_bricks
setblock ~-22 ~32 ~-26 stone_bricks
setblock ~-14 ~32 ~-26 stone_bricks
setblock ~-22 ~32 ~-24 stone_bricks
setblock ~-14 ~32 ~-24 stone_bricks
setblock ~-22 ~32 ~-22 stone_bricks
setblock ~-14 ~32 ~-22 stone_bricks
setblock ~-22 ~32 ~-20 stone_bricks
setblock ~-14 ~32 ~-20 stone_bricks
fill ~-18 ~31 ~-24 ~-18 ~35 ~-24 dark_oak_fence
setblock ~-18 ~36 ~-24 red_banner[rotation=0]
fill ~14 ~ ~8 ~22 ~30 ~16 stone_bricks
fill ~15 ~ ~9 ~21 ~29 ~15 air
fill ~14 ~ ~8 ~22 ~1 ~16 cobblestone
fill ~15 ~ ~9 ~21 ~1 ~15 air
fill ~15 ~19 ~9 ~21 ~19 ~15 dark_oak_planks
setblock ~15 ~ ~12 ladder[facing=east]
setblock ~15 ~1 ~12 ladder[facing=east]
setblock ~15 ~2 ~12 ladder[facing=east]
setblock ~15 ~3 ~12 ladder[facing=east]
setblock ~15 ~4 ~12 ladder[facing=east]
setblock ~15 ~5 ~12 ladder[facing=east]
setblock ~15 ~6 ~12 ladder[facing=east]
setblock ~15 ~7 ~12 ladder[facing=east]
setblock ~15 ~8 ~12 ladder[facing=east]
setblock ~15 ~9 ~12 ladder[facing=east]
setblock ~15 ~10 ~12 ladder[facing=east]
setblock ~15 ~11 ~12 ladder[facing=east]
setblock ~15 ~12 ~12 ladder[facing=east]
setblock ~15 ~13 ~12 ladder[facing=east]
setblock ~15 ~14 ~12 ladder[facing=east]
setblock ~15 ~15 ~12 ladder[facing=east]
setblock ~15 ~16 ~12 ladder[facing=east]
setblock ~15 ~17 ~12 ladder[facing=east]
setblock ~15 ~18 ~12 ladder[facing=east]
setblock ~15 ~19 ~12 ladder[facing=east]
setblock ~15 ~20 ~12 ladder[facing=east]
setblock ~15 ~21 ~12 ladder[facing=east]
setblock ~15 ~22 ~12 ladder[facing=east]
setblock ~15 ~23 ~12 ladder[facing=east]
setblock ~15 ~24 ~12 ladder[facing=east]
setblock ~15 ~25 ~12 ladder[facing=east]
setblock ~15 ~26 ~12 ladder[facing=east]
setblock ~15 ~27 ~12 ladder[facing=east]
setblock ~15 ~28 ~12 ladder[facing=east]
setblock ~15 ~29 ~12 ladder[facing=east]
setblock ~15 ~30 ~12 ladder[facing=east]
setblock ~21 ~ ~15 lantern[hanging=false]
setblock ~21 ~20 ~15 lantern[hanging=false]
fill ~14 ~20 ~10 ~14 ~21 ~10 air
fill ~16 ~20 ~8 ~16 ~21 ~8 air
fill ~22 ~24 ~12 ~22 ~25 ~12 iron_bars
fill ~18 ~24 ~16 ~18 ~25 ~16 iron_bars
fill ~14 ~31 ~8 ~22 ~31 ~8 stone_bricks
fill ~14 ~31 ~16 ~22 ~31 ~16 stone_bricks
fill ~14 ~31 ~8 ~14 ~31 ~16 stone_bricks
fill ~22 ~31 ~8 ~22 ~31 ~16 stone_bricks
setblock ~14 ~32 ~8 stone_bricks
setblock ~14 ~32 ~16 stone_bricks
setblock ~16 ~32 ~8 stone_bricks
setblock ~16 ~32 ~16 stone_bricks
setblock ~18 ~32 ~8 stone_bricks
setblock ~18 ~32 ~16 stone_bricks
setblock ~20 ~32 ~8 stone_bricks
setblock ~20 ~32 ~16 stone_bricks
setblock ~22 ~32 ~8 stone_bricks
setblock ~22 ~32 ~16 stone_bricks
setblock ~14 ~32 ~8 stone_bricks
setblock ~22 ~32 ~8 stone_bricks
setblock ~14 ~32 ~10 stone_bricks
setblock ~22 ~32 ~10 stone_bricks
setblock ~14 ~32 ~12 stone_bricks
setblock ~22 ~32 ~12 stone_bricks
setblock ~14 ~32 ~14 stone_bricks
setblock ~22 ~32 ~14 stone_bricks
setblock ~14 ~32 ~16 stone_bricks
setblock ~22 ~32 ~16 stone_bricks
fill ~18 ~31 ~12 ~18 ~35 ~12 dark_oak_fence
setblock ~18 ~36 ~12 red_banner[rotation=0]
fill ~-22 ~ ~8 ~-14 ~30 ~16 stone_bricks
fill ~-21 ~ ~9 ~-15 ~29 ~15 air
fill ~-22 ~ ~8 ~-14 ~1 ~16 cobblestone
fill ~-21 ~ ~9 ~-15 ~1 ~15 air
fill ~-21 ~19 ~9 ~-15 ~19 ~15 dark_oak_planks
setblock ~-21 ~ ~12 ladder[facing=east]
setblock ~-21 ~1 ~12 ladder[facing=east]
setblock ~-21 ~2 ~12 ladder[facing=east]
setblock ~-21 ~3 ~12 ladder[facing=east]
setblock ~-21 ~4 ~12 ladder[facing=east]
setblock ~-21 ~5 ~12 ladder[facing=east]
setblock ~-21 ~6 ~12 ladder[facing=east]
setblock ~-21 ~7 ~12 ladder[facing=east]
setblock ~-21 ~8 ~12 ladder[facing=east]
setblock ~-21 ~9 ~12 ladder[facing=east]
setblock ~-21 ~10 ~12 ladder[facing=east]
setblock ~-21 ~11 ~12 ladder[facing=east]
setblock ~-21 ~12 ~12 ladder[facing=east]
setblock ~-21 ~13 ~12 ladder[facing=east]
setblock ~-21 ~14 ~12 ladder[facing=east]
setblock ~-21 ~15 ~12 ladder[facing=east]
setblock ~-21 ~16 ~12 ladder[facing=east]
setblock ~-21 ~17 ~12 ladder[facing=east]
setblock ~-21 ~18 ~12 ladder[facing=east]
setblock ~-21 ~19 ~12 ladder[facing=east]
setblock ~-21 ~20 ~12 ladder[facing=east]
setblock ~-21 ~21 ~12 ladder[facing=east]
setblock ~-21 ~22 ~12 ladder[facing=east]
setblock ~-21 ~23 ~12 ladder[facing=east]
setblock ~-21 ~24 ~12 ladder[facing=east]
setblock ~-21 ~25 ~12 ladder[facing=east]
setblock ~-21 ~26 ~12 ladder[facing=east]
setblock ~-21 ~27 ~12 ladder[facing=east]
setblock ~-21 ~28 ~12 ladder[facing=east]
setblock ~-21 ~29 ~12 ladder[facing=east]
setblock ~-21 ~30 ~12 ladder[facing=east]
setblock ~-15 ~ ~15 lantern[hanging=false]
setblock ~-15 ~20 ~15 lantern[hanging=false]
fill ~-14 ~20 ~10 ~-14 ~21 ~10 air
fill ~-16 ~20 ~8 ~-16 ~21 ~8 air
fill ~-22 ~24 ~12 ~-22 ~25 ~12 iron_bars
fill ~-18 ~24 ~16 ~-18 ~25 ~16 iron_bars
fill ~-22 ~31 ~8 ~-14 ~31 ~8 stone_bricks
fill ~-22 ~31 ~16 ~-14 ~31 ~16 stone_bricks
fill ~-22 ~31 ~8 ~-22 ~31 ~16 stone_bricks
fill ~-14 ~31 ~8 ~-14 ~31 ~16 stone_bricks
setblock ~-22 ~32 ~8 stone_bricks
setblock ~-22 ~32 ~16 stone_bricks
setblock ~-20 ~32 ~8 stone_bricks
setblock ~-20 ~32 ~16 stone_bricks
setblock ~-18 ~32 ~8 stone_bricks
setblock ~-18 ~32 ~16 stone_bricks
setblock ~-16 ~32 ~8 stone_bricks
setblock ~-16 ~32 ~16 stone_bricks
setblock ~-14 ~32 ~8 stone_bricks
setblock ~-14 ~32 ~16 stone_bricks
setblock ~-22 ~32 ~8 stone_bricks
setblock ~-14 ~32 ~8 stone_bricks
setblock ~-22 ~32 ~10 stone_bricks
setblock ~-14 ~32 ~10 stone_bricks
setblock ~-22 ~32 ~12 stone_bricks
setblock ~-14 ~32 ~12 stone_bricks
setblock ~-22 ~32 ~14 stone_bricks
setblock ~-14 ~32 ~14 stone_bricks
setblock ~-22 ~32 ~16 stone_bricks
setblock ~-14 ~32 ~16 stone_bricks
fill ~-18 ~31 ~12 ~-18 ~35 ~12 dark_oak_fence
setblock ~-18 ~36 ~12 red_banner[rotation=0]
fill ~-6 ~20 ~-12 ~6 ~39 ~ stone_bricks
fill ~-5 ~20 ~-11 ~5 ~38 ~-1 air
fill ~-5 ~29 ~-11 ~5 ~29 ~-1 dark_oak_planks
setblock ~-5 ~20 ~-6 ladder[facing=east]
setblock ~-5 ~21 ~-6 ladder[facing=east]
setblock ~-5 ~22 ~-6 ladder[facing=east]
setblock ~-5 ~23 ~-6 ladder[facing=east]
setblock ~-5 ~24 ~-6 ladder[facing=east]
setblock ~-5 ~25 ~-6 ladder[facing=east]
setblock ~-5 ~26 ~-6 ladder[facing=east]
setblock ~-5 ~27 ~-6 ladder[facing=east]
setblock ~-5 ~28 ~-6 ladder[facing=east]
setblock ~-5 ~29 ~-6 ladder[facing=east]
setblock ~-5 ~30 ~-6 ladder[facing=east]
setblock ~-5 ~31 ~-6 ladder[facing=east]
setblock ~-5 ~32 ~-6 ladder[facing=east]
setblock ~-5 ~33 ~-6 ladder[facing=east]
setblock ~-5 ~34 ~-6 ladder[facing=east]
setblock ~-5 ~35 ~-6 ladder[facing=east]
setblock ~-5 ~36 ~-6 ladder[facing=east]
setblock ~-5 ~37 ~-6 ladder[facing=east]
setblock ~-5 ~38 ~-6 ladder[facing=east]
setblock ~-5 ~39 ~-6 ladder[facing=east]
setblock ~5 ~30 ~-1 lantern[hanging=false]
fill ~ ~20 ~ ~ ~21 ~ air
fill ~ ~25 ~-12 ~ ~26 ~-12 iron_bars
fill ~-6 ~25 ~-6 ~-6 ~26 ~-6 iron_bars
fill ~6 ~25 ~-6 ~6 ~26 ~-6 iron_bars
fill ~ ~33 ~-12 ~ ~34 ~-12 iron_bars
fill ~-6 ~33 ~-6 ~-6 ~34 ~-6 iron_bars
fill ~6 ~33 ~-6 ~6 ~34 ~-6 iron_bars
fill ~-7 ~40 ~-13 ~7 ~40 ~1 dark_oak_planks
fill ~-6 ~41 ~-12 ~6 ~41 ~ dark_oak_planks
fill ~-5 ~42 ~-11 ~5 ~42 ~-1 dark_oak_planks
fill ~-4 ~43 ~-10 ~4 ~43 ~-2 dark_oak_planks
fill ~-3 ~44 ~-9 ~3 ~44 ~-3 dark_oak_planks
fill ~-2 ~45 ~-8 ~2 ~45 ~-4 dark_oak_planks
fill ~-1 ~46 ~-7 ~1 ~46 ~-5 dark_oak_planks
fill ~ ~47 ~-6 ~ ~47 ~-6 dark_oak_planks
fill ~ ~48 ~-6 ~ ~51 ~-6 dark_oak_fence
setblock ~ ~52 ~-6 red_banner[rotation=0]
fill ~-16 ~ ~-22 ~16 ~17 ~10 air
fill ~-16 ~-1 ~-22 ~16 ~-1 ~10 polished_blackstone_bricks
fill ~-3 ~ ~11 ~3 ~8 ~12 air
fill ~-4 ~ ~12 ~-4 ~9 ~12 chiseled_stone_bricks
fill ~4 ~ ~12 ~4 ~9 ~12 chiseled_stone_bricks
fill ~-4 ~9 ~12 ~4 ~9 ~12 chiseled_stone_bricks
fill ~-3 ~8 ~12 ~3 ~8 ~12 chiseled_stone_bricks
fill ~-2 ~ ~13 ~-2 ~4 ~13 air
setblock ~-9 ~9 ~13 red_wall_banner[facing=south]
setblock ~9 ~9 ~13 red_wall_banner[facing=south]
setblock ~-13 ~9 ~13 black_wall_banner[facing=south]
setblock ~13 ~9 ~13 black_wall_banner[facing=south]
fill ~16 ~5 ~-17 ~17 ~13 ~-15 gray_stained_glass
fill ~-17 ~5 ~-17 ~-16 ~13 ~-15 gray_stained_glass
fill ~16 ~5 ~-9 ~17 ~13 ~-7 gray_stained_glass
fill ~-17 ~5 ~-9 ~-16 ~13 ~-7 gray_stained_glass
fill ~16 ~5 ~-1 ~17 ~13 ~1 gray_stained_glass
fill ~-17 ~5 ~-1 ~-16 ~13 ~1 gray_stained_glass
fill ~16 ~5 ~5 ~17 ~13 ~7 gray_stained_glass
fill ~-17 ~5 ~5 ~-16 ~13 ~7 gray_stained_glass
fill ~-13 ~5 ~-24 ~-11 ~13 ~-23 gray_stained_glass
fill ~11 ~5 ~-24 ~13 ~13 ~-23 gray_stained_glass
