fill ~-1 ~ ~-13 ~1 ~ ~10 red_carpet
fill ~-3 ~ ~10 ~3 ~ ~10 red_carpet
fill ~-9 ~ ~-22 ~9 ~ ~-13 polished_blackstone_bricks
fill ~-7 ~1 ~-22 ~7 ~1 ~-14 polished_blackstone_bricks
fill ~-5 ~2 ~-22 ~5 ~2 ~-16 polished_blackstone_bricks
fill ~-9 ~ ~-12 ~9 ~ ~-12 polished_blackstone_brick_stairs[facing=north]
fill ~-7 ~1 ~-13 ~7 ~1 ~-13 polished_blackstone_brick_stairs[facing=north]
fill ~-5 ~2 ~-15 ~5 ~2 ~-15 polished_blackstone_brick_stairs[facing=north]
fill ~-2 ~ ~-12 ~2 ~ ~-12 red_carpet
fill ~-1 ~1 ~-13 ~1 ~1 ~-13 red_carpet
fill ~-1 ~2 ~-14 ~1 ~2 ~-14 red_carpet
fill ~-2 ~3 ~-21 ~2 ~3 ~-20 iron_block
setblock ~ ~3 ~-19 polished_blackstone_brick_stairs[facing=north]
setblock ~-1 ~3 ~-19 stone_brick_wall
setblock ~1 ~3 ~-19 stone_brick_wall
fill ~-1 ~4 ~-21 ~1 ~6 ~-21 iron_block
setblock ~ ~4 ~-20 iron_block
fill ~-3 ~3 ~-22 ~-3 ~8 ~-22 iron_bars
fill ~-2 ~3 ~-22 ~-2 ~10 ~-22 iron_bars
fill ~-1 ~3 ~-22 ~-1 ~12 ~-22 iron_bars
fill ~ ~3 ~-22 ~ ~14 ~-22 iron_bars
fill ~1 ~3 ~-22 ~1 ~12 ~-22 iron_bars
fill ~2 ~3 ~-22 ~2 ~10 ~-22 iron_bars
fill ~3 ~3 ~-22 ~3 ~8 ~-22 iron_bars
fill ~-4 ~7 ~-22 ~-4 ~7 ~-22 iron_bars
fill ~-3 ~7 ~-22 ~-3 ~9 ~-22 iron_bars
fill ~-2 ~7 ~-22 ~-2 ~11 ~-22 iron_bars
fill ~-1 ~7 ~-22 ~-1 ~13 ~-22 iron_bars
fill ~ ~7 ~-22 ~ ~15 ~-22 iron_bars
fill ~1 ~7 ~-22 ~1 ~13 ~-22 iron_bars
fill ~2 ~7 ~-22 ~2 ~11 ~-22 iron_bars
fill ~3 ~7 ~-22 ~3 ~9 ~-22 iron_bars
fill ~4 ~7 ~-22 ~4 ~7 ~-22 iron_bars
fill ~-6 ~3 ~-20 ~-6 ~3 ~-20 polished_blackstone_wall
setblock ~-6 ~4 ~-20 lantern[hanging=false]
fill ~6 ~3 ~-20 ~6 ~3 ~-20 polished_blackstone_wall
setblock ~6 ~4 ~-20 lantern[hanging=false]
setblock ~-7 ~8 ~-22 red_wall_banner[facing=south]
setblock ~7 ~8 ~-22 red_wall_banner[facing=south]
setblock ~-11 ~8 ~-22 black_wall_banner[facing=south]
setblock ~11 ~8 ~-22 black_wall_banner[facing=south]
setblock ~-15 ~8 ~-22 light_gray_wall_banner[facing=south]
setblock ~15 ~8 ~-22 light_gray_wall_banner[facing=south]
fill ~-9 ~ ~-10 ~-9 ~17 ~-10 polished_deepslate
setblock ~-9 ~ ~-10 chiseled_stone_bricks
setblock ~-9 ~16 ~-10 chiseled_stone_bricks
fill ~-9 ~ ~-4 ~-9 ~17 ~-4 polished_deepslate
setblock ~-9 ~ ~-4 chiseled_stone_bricks
setblock ~-9 ~16 ~-4 chiseled_stone_bricks
fill ~-9 ~ ~2 ~-9 ~17 ~2 polished_deepslate
setblock ~-9 ~ ~2 chiseled_stone_bricks
setblock ~-9 ~16 ~2 chiseled_stone_bricks
fill ~-9 ~ ~8 ~-9 ~17 ~8 polished_deepslate
setblock ~-9 ~ ~8 chiseled_stone_bricks
setblock ~-9 ~16 ~8 chiseled_stone_bricks
fill ~9 ~ ~-10 ~9 ~17 ~-10 polished_deepslate
setblock ~9 ~ ~-10 chiseled_stone_bricks
setblock ~9 ~16 ~-10 chiseled_stone_bricks
fill ~9 ~ ~-4 ~9 ~17 ~-4 polished_deepslate
setblock ~9 ~ ~-4 chiseled_stone_bricks
setblock ~9 ~16 ~-4 chiseled_stone_bricks
fill ~9 ~ ~2 ~9 ~17 ~2 polished_deepslate
setblock ~9 ~ ~2 chiseled_stone_bricks
setblock ~9 ~16 ~2 chiseled_stone_bricks
fill ~9 ~ ~8 ~9 ~17 ~8 polished_deepslate
setblock ~9 ~ ~8 chiseled_stone_bricks
setblock ~9 ~16 ~8 chiseled_stone_bricks
fill ~-16 ~17 ~-19 ~16 ~17 ~-19 dark_oak_log[axis=x]
setblock ~-12 ~16 ~-19 lantern[hanging=true]
setblock ~-5 ~16 ~-19 lantern[hanging=true]
setblock ~5 ~16 ~-19 lantern[hanging=true]
setblock ~12 ~16 ~-19 lantern[hanging=true]
fill ~-16 ~17 ~-11 ~16 ~17 ~-11 dark_oak_log[axis=x]
setblock ~-12 ~16 ~-11 lantern[hanging=true]
setblock ~-5 ~16 ~-11 lantern[hanging=true]
setblock ~5 ~16 ~-11 lantern[hanging=true]
setblock ~12 ~16 ~-11 lantern[hanging=true]
fill ~-16 ~17 ~-3 ~16 ~17 ~-3 dark_oak_log[axis=x]
setblock ~-12 ~16 ~-3 lantern[hanging=true]
setblock ~-5 ~16 ~-3 lantern[hanging=true]
setblock ~5 ~16 ~-3 lantern[hanging=true]
setblock ~12 ~16 ~-3 lantern[hanging=true]
fill ~-16 ~17 ~5 ~16 ~17 ~5 dark_oak_log[axis=x]
setblock ~-12 ~16 ~5 lantern[hanging=true]
setblock ~-5 ~16 ~5 lantern[hanging=true]
setblock ~5 ~16 ~5 lantern[hanging=true]
setblock ~12 ~16 ~5 lantern[hanging=true]
fill ~-5 ~ ~-10 ~-5 ~ ~8 spruce_planks
setblock ~-6 ~ ~-10 spruce_stairs[facing=west]
setblock ~-4 ~ ~-10 spruce_stairs[facing=east]
setblock ~-6 ~ ~-8 spruce_stairs[facing=west]
setblock ~-4 ~ ~-8 spruce_stairs[facing=east]
setblock ~-6 ~ ~-6 spruce_stairs[facing=west]
setblock ~-4 ~ ~-6 spruce_stairs[facing=east]
setblock ~-6 ~ ~-4 spruce_stairs[facing=west]
setblock ~-4 ~ ~-4 spruce_stairs[facing=east]
setblock ~-6 ~ ~-2 spruce_stairs[facing=west]
setblock ~-4 ~ ~-2 spruce_stairs[facing=east]
setblock ~-6 ~ ~ spruce_stairs[facing=west]
setblock ~-4 ~ ~ spruce_stairs[facing=east]
setblock ~-6 ~ ~2 spruce_stairs[facing=west]
setblock ~-4 ~ ~2 spruce_stairs[facing=east]
setblock ~-6 ~ ~4 spruce_stairs[facing=west]
setblock ~-4 ~ ~4 spruce_stairs[facing=east]
setblock ~-6 ~ ~6 spruce_stairs[facing=west]
setblock ~-4 ~ ~6 spruce_stairs[facing=east]
setblock ~-6 ~ ~8 spruce_stairs[facing=west]
setblock ~-4 ~ ~8 spruce_stairs[facing=east]
fill ~5 ~ ~-10 ~5 ~ ~8 spruce_planks
setblock ~4 ~ ~-10 spruce_stairs[facing=west]
setblock ~6 ~ ~-10 spruce_stairs[facing=east]
setblock ~4 ~ ~-8 spruce_stairs[facing=west]
setblock ~6 ~ ~-8 spruce_stairs[facing=east]
setblock ~4 ~ ~-6 spruce_stairs[facing=west]
setblock ~6 ~ ~-6 spruce_stairs[facing=east]
setblock ~4 ~ ~-4 spruce_stairs[facing=west]
setblock ~6 ~ ~-4 spruce_stairs[facing=east]
setblock ~4 ~ ~-2 spruce_stairs[facing=west]
setblock ~6 ~ ~-2 spruce_stairs[facing=east]
setblock ~4 ~ ~ spruce_stairs[facing=west]
setblock ~6 ~ ~ spruce_stairs[facing=east]
setblock ~4 ~ ~2 spruce_stairs[facing=west]
setblock ~6 ~ ~2 spruce_stairs[facing=east]
setblock ~4 ~ ~4 spruce_stairs[facing=west]
setblock ~6 ~ ~4 spruce_stairs[facing=east]
setblock ~4 ~ ~6 spruce_stairs[facing=west]
setblock ~6 ~ ~6 spruce_stairs[facing=east]
setblock ~4 ~ ~8 spruce_stairs[facing=west]
setblock ~6 ~ ~8 spruce_stairs[facing=east]
fill ~-15 ~ ~9 ~-15 ~2 ~9 stone_bricks
setblock ~-15 ~ ~8 campfire[lit=true]
fill ~15 ~ ~9 ~15 ~2 ~9 stone_bricks
setblock ~15 ~ ~8 campfire[lit=true]
setblock ~-16 ~4 ~-14 wall_torch[facing=east]
setblock ~16 ~4 ~-14 wall_torch[facing=west]
setblock ~-16 ~4 ~-6 wall_torch[facing=east]
setblock ~16 ~4 ~-6 wall_torch[facing=west]
setblock ~-16 ~4 ~2 wall_torch[facing=east]
setblock ~16 ~4 ~2 wall_torch[facing=west]
setblock ~-16 ~4 ~8 wall_torch[facing=east]
setblock ~16 ~4 ~8 wall_torch[facing=west]
