fill ~-27 ~-1 ~-32 ~27 ~-1 ~20 gravel
fill ~-2 ~-1 ~13 ~2 ~-1 ~36 stone_bricks
fill ~-3 ~-1 ~13 ~-3 ~-1 ~36 cobblestone
fill ~3 ~-1 ~13 ~3 ~-1 ~36 cobblestone
fill ~-4 ~ ~16 ~-4 ~1 ~16 stone_brick_wall
setblock ~-4 ~2 ~16 lantern[hanging=false]
fill ~4 ~ ~16 ~4 ~1 ~16 stone_brick_wall
setblock ~4 ~2 ~16 lantern[hanging=false]
fill ~-4 ~ ~22 ~-4 ~1 ~22 stone_brick_wall
setblock ~-4 ~2 ~22 lantern[hanging=false]
fill ~4 ~ ~22 ~4 ~1 ~22 stone_brick_wall
setblock ~4 ~2 ~22 lantern[hanging=false]
fill ~-4 ~ ~28 ~-4 ~1 ~28 stone_brick_wall
setblock ~-4 ~2 ~28 lantern[hanging=false]
fill ~4 ~ ~28 ~4 ~1 ~28 stone_brick_wall
setblock ~4 ~2 ~28 lantern[hanging=false]
fill ~-4 ~ ~34 ~-4 ~1 ~34 stone_brick_wall
setblock ~-4 ~2 ~34 lantern[hanging=false]
fill ~4 ~ ~34 ~4 ~1 ~34 stone_brick_wall
setblock ~4 ~2 ~34 lantern[hanging=false]
fill ~-38 ~-1 ~12 ~-24 ~-1 ~22 stone_bricks
fill ~-38 ~ ~12 ~-24 ~6 ~22 stone_bricks
fill ~-37 ~ ~13 ~-25 ~5 ~21 air
fill ~-37 ~6 ~13 ~-25 ~6 ~21 dark_oak_planks
fill ~-39 ~7 ~11 ~-23 ~7 ~23 dark_oak_planks
fill ~-39 ~8 ~12 ~-23 ~8 ~22 dark_oak_planks
fill ~-39 ~9 ~13 ~-23 ~9 ~21 dark_oak_planks
fill ~-39 ~10 ~14 ~-23 ~10 ~20 dark_oak_planks
fill ~-39 ~11 ~15 ~-23 ~11 ~19 dark_oak_planks
fill ~-39 ~12 ~16 ~-23 ~12 ~18 dark_oak_planks
fill ~-32 ~ ~12 ~-30 ~2 ~12 air
fill ~-32 ~ ~9 ~-30 ~ ~11 stone_bricks
setblock ~-36 ~ ~21 chest[facing=north]
setblock ~-34 ~ ~21 chest[facing=north]
setblock ~-32 ~ ~21 chest[facing=north]
setblock ~-30 ~ ~21 chest[facing=north]
setblock ~-28 ~ ~21 chest[facing=north]
setblock ~-26 ~ ~21 chest[facing=north]
setblock ~-36 ~ ~13 smithing_table
setblock ~-34 ~ ~13 anvil
setblock ~-28 ~ ~13 grindstone[face=floor]
setblock ~-26 ~ ~13 blast_furnace[facing=south]
setblock ~-34 ~5 ~17 lantern[hanging=true]
setblock ~-28 ~5 ~17 lantern[hanging=true]
setblock ~-37 ~3 ~17 wall_torch[facing=east]
setblock ~-25 ~3 ~17 wall_torch[facing=west]
fill ~24 ~-1 ~12 ~38 ~-1 ~36 grass_block
fill ~26 ~-2 ~26 ~31 ~-1 ~30 water
fill ~33 ~ ~19 ~34 ~9 ~20 oak_log[axis=y]
setblock ~27 ~12 ~20 oak_leaves[persistent=true]
setblock ~28 ~10 ~20 oak_leaves[persistent=true]
setblock ~28 ~11 ~18 oak_leaves[persistent=true]
setblock ~28 ~11 ~19 oak_leaves[persistent=true]
setblock ~28 ~11 ~20 oak_leaves[persistent=true]
setblock ~28 ~11 ~23 oak_leaves[persistent=true]
setblock ~28 ~12 ~17 oak_leaves[persistent=true]
setblock ~28 ~12 ~19 oak_leaves[persistent=true]
setblock ~28 ~12 ~20 oak_leaves[persistent=true]
setblock ~28 ~12 ~22 oak_leaves[persistent=true]
setblock ~28 ~13 ~19 oak_leaves[persistent=true]
setblock ~29 ~10 ~17 oak_leaves[persistent=true]
setblock ~29 ~10 ~18 oak_leaves[persistent=true]
setblock ~29 ~10 ~19 oak_leaves[persistent=true]
setblock ~29 ~10 ~20 oak_leaves[persistent=true]
setblock ~29 ~10 ~21 oak_leaves[persistent=true]
setblock ~29 ~10 ~22 oak_leaves[persistent=true]
setblock ~29 ~11 ~15 oak_leaves[persistent=true]
setblock ~29 ~11 ~17 oak_leaves[persistent=true]
setblock ~29 ~11 ~18 oak_leaves[persistent=true]
setblock ~29 ~11 ~20 oak_leaves[persistent=true]
setblock ~29 ~11 ~21 oak_leaves[persistent=true]
setblock ~29 ~11 ~22 oak_leaves[persistent=true]
setblock ~29 ~11 ~24 oak_leaves[persistent=true]
setblock ~29 ~12 ~16 oak_leaves[persistent=true]
setblock ~29 ~12 ~19 oak_leaves[persistent=true]
setblock ~29 ~12 ~21 oak_leaves[persistent=true]
setblock ~29 ~12 ~23 oak_leaves[persistent=true]
setblock ~29 ~12 ~24 oak_leaves[persistent=true]
setblock ~29 ~13 ~16 oak_leaves[persistent=true]
setblock ~29 ~13 ~18 oak_leaves[persistent=true]
setblock ~29 ~13 ~22 oak_leaves[persistent=true]
setblock ~29 ~14 ~20 oak_leaves[persistent=true]
setblock ~30 ~9 ~18 oak_leaves[persistent=true]
setblock ~30 ~9 ~20 oak_leaves[persistent=true]
setblock ~30 ~10 ~17 oak_leaves[persistent=true]
setblock ~30 ~10 ~18 oak_leaves[persistent=true]
setblock ~30 ~10 ~19 oak_leaves[persistent=true]
setblock ~30 ~10 ~20 oak_leaves[persistent=true]
setblock ~30 ~10 ~21 oak_leaves[persistent=true]
setblock ~30 ~10 ~22 oak_leaves[persistent=true]
setblock ~30 ~11 ~14 oak_leaves[persistent=true]
setblock ~30 ~11 ~15 oak_leaves[persistent=true]
setblock ~30 ~11 ~17 oak_leaves[persistent=true]
setblock ~30 ~11 ~18 oak_leaves[persistent=true]
setblock ~30 ~11 ~19 oak_leaves[persistent=true]
setblock ~30 ~11 ~20 oak_leaves[persistent=true]
setblock ~30 ~11 ~22 oak_leaves[persistent=true]
setblock ~30 ~11 ~23 oak_leaves[persistent=true]
setblock ~30 ~11 ~24 oak_leaves[persistent=true]
setblock ~30 ~12 ~14 oak_leaves[persistent=true]
setblock ~30 ~12 ~17 oak_leaves[persistent=true]
setblock ~30 ~12 ~18 oak_leaves[persistent=true]
setblock ~30 ~12 ~20 oak_leaves[persistent=true]
setblock ~30 ~12 ~22 oak_leaves[persistent=true]
setblock ~30 ~12 ~23 oak_leaves[persistent=true]
setblock ~30 ~12 ~24 oak_leaves[persistent=true]
setblock ~30 ~13 ~20 oak_leaves[persistent=true]
setblock ~30 ~13 ~21 oak_leaves[persistent=true]
setblock ~30 ~14 ~17 oak_leaves[persistent=true]
setblock ~31 ~9 ~16 oak_leaves[persistent=true]
setblock ~31 ~9 ~17 oak_leaves[persistent=true]
setblock ~31 ~9 ~20 oak_leaves[persistent=true]
setblock ~31 ~10 ~16 oak_leaves[persistent=true]
setblock ~31 ~10 ~18 oak_leaves[persistent=true]
setblock ~31 ~10 ~19 oak_leaves[persistent=true]
setblock ~31 ~10 ~20 oak_leaves[persistent=true]
setblock ~31 ~10 ~21 oak_leaves[persistent=true]
setblock ~31 ~10 ~22 oak_leaves[persistent=true]
setblock ~31 ~11 ~14 oak_leaves[persistent=true]
setblock ~31 ~11 ~16 oak_leaves[persistent=true]
setblock ~31 ~11 ~17 oak_leaves[persistent=true]
setblock ~31 ~11 ~18 oak_leaves[persistent=true]
setblock ~31 ~11 ~19 oak_leaves[persistent=true]
setblock ~31 ~11 ~20 oak_leaves[persistent=true]
setblock ~31 ~11 ~21 oak_leaves[persistent=true]
setblock ~31 ~11 ~22 oak_leaves[persistent=true]
setblock ~31 ~11 ~23 oak_leaves[persistent=true]
setblock ~31 ~12 ~17 oak_leaves[persistent=true]
setblock ~31 ~12 ~20 oak_leaves[persistent=true]
setblock ~31 ~12 ~21 oak_leaves[persistent=true]
setblock ~31 ~12 ~22 oak_leaves[persistent=true]
setblock ~31 ~13 ~17 oak_leaves[persistent=true]
setblock ~31 ~13 ~19 oak_leaves[persistent=true]
setblock ~31 ~13 ~20 oak_leaves[persistent=true]
setblock ~31 ~13 ~21 oak_leaves[persistent=true]
setblock ~31 ~13 ~22 oak_leaves[persistent=true]
setblock ~31 ~14 ~16 oak_leaves[persistent=true]
setblock ~31 ~14 ~17 oak_leaves[persistent=true]
setblock ~31 ~14 ~18 oak_leaves[persistent=true]
setblock ~31 ~14 ~20 oak_leaves[persistent=true]
setblock ~31 ~14 ~23 oak_leaves[persistent=true]
setblock ~32 ~9 ~15 oak_leaves[persistent=true]
setblock ~32 ~9 ~16 oak_leaves[persistent=true]
setblock ~32 ~9 ~17 oak_leaves[persistent=true]
setblock ~32 ~9 ~18 oak_leaves[persistent=true]
setblock ~32 ~9 ~19 oak_leaves[persistent=true]
setblock ~32 ~9 ~20 oak_leaves[persistent=true]
setblock ~32 ~9 ~21 oak_leaves[persistent=true]
setblock ~32 ~9 ~22 oak_leaves[persistent=true]
setblock ~32 ~10 ~14 oak_leaves[persistent=true]
setblock ~32 ~10 ~16 oak_leaves[persistent=true]
setblock ~32 ~10 ~17 oak_leaves[persistent=true]
setblock ~32 ~10 ~18 oak_leaves[persistent=true]
setblock ~32 ~10 ~19 oak_leaves[persistent=true]
setblock ~32 ~10 ~20 oak_leaves[persistent=true]
setblock ~32 ~10 ~21 oak_leaves[persistent=true]
setblock ~32 ~10 ~22 oak_leaves[persistent=true]
setblock ~32 ~10 ~23 oak_leaves[persistent=true]
setblock ~32 ~10 ~25 oak_leaves[persistent=true]
setblock ~32 ~11 ~14 oak_leaves[persistent=true]
setblock ~32 ~11 ~15 oak_leaves[persistent=true]
setblock ~32 ~11 ~17 oak_leaves[persistent=true]
setblock ~32 ~11 ~18 oak_leaves[persistent=true]
setblock ~32 ~11 ~19 oak_leaves[persistent=true]
setblock ~32 ~11 ~20 oak_leaves[persistent=true]
setblock ~32 ~11 ~21 oak_leaves[persistent=true]
setblock ~32 ~11 ~22 oak_leaves[persistent=true]
setblock ~32 ~11 ~23 oak_leaves[persistent=true]
setblock ~32 ~11 ~24 oak_leaves[persistent=true]
setblock ~32 ~12 ~14 oak_leaves[persistent=true]
setblock ~32 ~12 ~16 oak_leaves[persistent=true]
setblock ~32 ~12 ~17 oak_leaves[persistent=true]
setblock ~32 ~12 ~18 oak_leaves[persistent=true]
setblock ~32 ~12 ~19 oak_leaves[persistent=true]
setblock ~32 ~12 ~20 oak_leaves[persistent=true]
setblock ~32 ~12 ~21 oak_leaves[persistent=true]
setblock ~32 ~12 ~22 oak_leaves[persistent=true]
setblock ~32 ~12 ~23 oak_leaves[persistent=true]
setblock ~32 ~12 ~24 oak_leaves[persistent=true]
setblock ~32 ~12 ~25 oak_leaves[persistent=true]
setblock ~32 ~13 ~15 oak_leaves[persistent=true]
setblock ~32 ~13 ~18 oak_leaves[persistent=true]
setblock ~32 ~13 ~19 oak_leaves[persistent=true]
setblock ~32 ~13 ~21 oak_leaves[persistent=true]
setblock ~32 ~13 ~22 oak_leaves[persistent=true]
setblock ~32 ~13 ~23 oak_leaves[persistent=true]
setblock ~32 ~14 ~17 oak_leaves[persistent=true]
setblock ~32 ~14 ~19 oak_leaves[persistent=true]
setblock ~32 ~14 ~20 oak_leaves[persistent=true]
setblock ~32 ~14 ~23 oak_leaves[persistent=true]
setblock ~33 ~9 ~16 oak_leaves[persistent=true]
setblock ~33 ~9 ~18 oak_leaves[persistent=true]
setblock ~33 ~9 ~20 oak_leaves[persistent=true]
setblock ~33 ~9 ~24 oak_leaves[persistent=true]
setblock ~33 ~10 ~15 oak_leaves[persistent=true]
setblock ~33 ~10 ~16 oak_leaves[persistent=true]
setblock ~33 ~10 ~17 oak_leaves[persistent=true]
setblock ~33 ~10 ~18 oak_leaves[persistent=true]
setblock ~33 ~10 ~19 oak_leaves[persistent=true]
setblock ~33 ~10 ~20 oak_leaves[persistent=true]
setblock ~33 ~10 ~21 oak_leaves[persistent=true]
setblock ~33 ~10 ~22 oak_leaves[persistent=true]
setblock ~33 ~10 ~23 oak_leaves[persistent=true]
setblock ~33 ~10 ~24 oak_leaves[persistent=true]
setblock ~33 ~10 ~25 oak_leaves[persistent=true]
setblock ~33 ~11 ~16 oak_leaves[persistent=true]
setblock ~33 ~11 ~17 oak_leaves[persistent=true]
setblock ~33 ~11 ~18 oak_leaves[persistent=true]
setblock ~33 ~11 ~19 oak_leaves[persistent=true]
setblock ~33 ~11 ~20 oak_leaves[persistent=true]
setblock ~33 ~11 ~21 oak_leaves[persistent=true]
setblock ~33 ~11 ~22 oak_leaves[persistent=true]
setblock ~33 ~11 ~23 oak_leaves[persistent=true]
setblock ~33 ~11 ~25 oak_leaves[persistent=true]
setblock ~33 ~12 ~14 oak_leaves[persistent=true]
setblock ~33 ~12 ~15 oak_leaves[persistent=true]
setblock ~33 ~12 ~17 oak_leaves[persistent=true]
setblock ~33 ~12 ~18 oak_leaves[persistent=true]
setblock ~33 ~12 ~19 oak_leaves[persistent=true]
setblock ~33 ~12 ~20 oak_leaves[persistent=true]
setblock ~33 ~12 ~21 oak_leaves[persistent=true]
setblock ~33 ~12 ~22 oak_leaves[persistent=true]
setblock ~33 ~12 ~24 oak_leaves[persistent=true]
setblock ~33 ~13 ~15 oak_leaves[persistent=true]
setblock ~33 ~13 ~16 oak_leaves[persistent=true]
setblock ~33 ~13 ~17 oak_leaves[persistent=true]
setblock ~33 ~13 ~18 oak_leaves[persistent=true]
setblock ~33 ~13 ~19 oak_leaves[persistent=true]
setblock ~33 ~13 ~20 oak_leaves[persistent=true]
setblock ~33 ~13 ~21 oak_leaves[persistent=true]
setblock ~33 ~13 ~22 oak_leaves[persistent=true]
setblock ~33 ~13 ~23 oak_leaves[persistent=true]
setblock ~33 ~13 ~24 oak_leaves[persistent=true]
setblock ~33 ~14 ~18 oak_leaves[persistent=true]
setblock ~33 ~14 ~20 oak_leaves[persistent=true]
setblock ~33 ~14 ~24 oak_leaves[persistent=true]
setblock ~34 ~9 ~16 oak_leaves[persistent=true]
setblock ~34 ~9 ~18 oak_leaves[persistent=true]
setblock ~34 ~9 ~19 oak_leaves[persistent=true]
setblock ~34 ~9 ~20 oak_leaves[persistent=true]
setblock ~34 ~9 ~21 oak_leaves[persistent=true]
setblock ~34 ~9 ~22 oak_leaves[persistent=true]
setblock ~34 ~10 ~15 oak_leaves[persistent=true]
setblock ~34 ~10 ~16 oak_leaves[persistent=true]
setblock ~34 ~10 ~17 oak_leaves[persistent=true]
setblock ~34 ~10 ~18 oak_leaves[persistent=true]
setblock ~34 ~10 ~19 oak_leaves[persistent=true]
setblock ~34 ~10 ~21 oak_leaves[persistent=true]
setblock ~34 ~10 ~22 oak_leaves[persistent=true]
setblock ~34 ~10 ~24 oak_leaves[persistent=true]
setblock ~34 ~11 ~15 oak_leaves[persistent=true]
setblock ~34 ~11 ~16 oak_leaves[persistent=true]
setblock ~34 ~11 ~17 oak_leaves[persistent=true]
setblock ~34 ~11 ~18 oak_leaves[persistent=true]
setblock ~34 ~11 ~19 oak_leaves[persistent=true]
setblock ~34 ~11 ~20 oak_leaves[persistent=true]
setblock ~34 ~11 ~21 oak_leaves[persistent=true]
setblock ~34 ~11 ~22 oak_leaves[persistent=true]
setblock ~34 ~11 ~23 oak_leaves[persistent=true]
setblock ~34 ~11 ~24 oak_leaves[persistent=true]
setblock ~34 ~11 ~26 oak_leaves[persistent=true]
setblock ~34 ~12 ~15 oak_leaves[persistent=true]
setblock ~34 ~12 ~16 oak_leaves[persistent=true]
setblock ~34 ~12 ~17 oak_leaves[persistent=true]
setblock ~34 ~12 ~18 oak_leaves[persistent=true]
setblock ~34 ~12 ~19 oak_leaves[persistent=true]
setblock ~34 ~12 ~20 oak_leaves[persistent=true]
setblock ~34 ~12 ~21 oak_leaves[persistent=true]
setblock ~34 ~12 ~22 oak_leaves[persistent=true]
setblock ~34 ~12 ~23 oak_leaves[persistent=true]
setblock ~34 ~12 ~25 oak_leaves[persistent=true]
setblock ~34 ~13 ~14 oak_leaves[persistent=true]
setblock ~34 ~13 ~15 oak_leaves[persistent=true]
setblock ~34 ~13 ~17 oak_leaves[persistent=true]
setblock ~34 ~13 ~18 oak_leaves[persistent=true]
setblock ~34 ~13 ~19 oak_leaves[persistent=true]
setblock ~34 ~13 ~21 oak_leaves[persistent=true]
setblock ~34 ~13 ~23 oak_leaves[persistent=true]
setblock ~34 ~14 ~16 oak_leaves[persistent=true]
setblock ~34 ~14 ~18 oak_leaves[persistent=true]
setblock ~34 ~14 ~19 oak_leaves[persistent=true]
setblock ~34 ~14 ~20 oak_leaves[persistent=true]
setblock ~35 ~9 ~18 oak_leaves[persistent=true]
setblock ~35 ~9 ~19 oak_leaves[persistent=true]
setblock ~35 ~9 ~20 oak_leaves[persistent=true]
setblock ~35 ~9 ~21 oak_leaves[persistent=true]
setblock ~35 ~9 ~22 oak_leaves[persistent=true]
setblock ~35 ~10 ~15 oak_leaves[persistent=true]
setblock ~35 ~10 ~16 oak_leaves[persistent=true]
setblock ~35 ~10 ~18 oak_leaves[persistent=true]
setblock ~35 ~10 ~19 oak_leaves[persistent=true]
setblock ~35 ~10 ~20 oak_leaves[persistent=true]
setblock ~35 ~10 ~21 oak_leaves[persistent=true]
setblock ~35 ~10 ~22 oak_leaves[persistent=true]
setblock ~35 ~10 ~23 oak_leaves[persistent=true]
setblock ~35 ~10 ~24 oak_leaves[persistent=true]
setblock ~35 ~11 ~14 oak_leaves[persistent=true]
setblock ~35 ~11 ~15 oak_leaves[persistent=true]
setblock ~35 ~11 ~16 oak_leaves[persistent=true]
setblock ~35 ~11 ~17 oak_leaves[persistent=true]
setblock ~35 ~11 ~18 oak_leaves[persistent=true]
setblock ~35 ~11 ~19 oak_leaves[persistent=true]
setblock ~35 ~11 ~20 oak_leaves[persistent=true]
setblock ~35 ~11 ~21 oak_leaves[persistent=true]
setblock ~35 ~11 ~23 oak_leaves[persistent=true]
setblock ~35 ~12 ~15 oak_leaves[persistent=true]
setblock ~35 ~12 ~16 oak_leaves[persistent=true]
setblock ~35 ~12 ~17 oak_leaves[persistent=true]
setblock ~35 ~12 ~18 oak_leaves[persistent=true]
setblock ~35 ~12 ~19 oak_leaves[persistent=true]
setblock ~35 ~12 ~20 oak_leaves[persistent=true]
setblock ~35 ~12 ~21 oak_leaves[persistent=true]
setblock ~35 ~12 ~22 oak_leaves[persistent=true]
setblock ~35 ~12 ~23 oak_leaves[persistent=true]
setblock ~35 ~12 ~24 oak_leaves[persistent=true]
setblock ~35 ~12 ~25 oak_leaves[persistent=true]
setblock ~35 ~13 ~15 oak_leaves[persistent=true]
setblock ~35 ~13 ~16 oak_leaves[persistent=true]
setblock ~35 ~13 ~17 oak_leaves[persistent=true]
setblock ~35 ~13 ~18 oak_leaves[persistent=true]
setblock ~35 ~13 ~19 oak_leaves[persistent=true]
setblock ~35 ~13 ~20 oak_leaves[persistent=true]
setblock ~35 ~13 ~21 oak_leaves[persistent=true]
setblock ~35 ~13 ~22 oak_leaves[persistent=true]
setblock ~35 ~14 ~16 oak_leaves[persistent=true]
setblock ~35 ~14 ~17 oak_leaves[persistent=true]
setblock ~35 ~14 ~19 oak_leaves[persistent=true]
setblock ~35 ~14 ~20 oak_leaves[persistent=true]
setblock ~36 ~9 ~16 oak_leaves[persistent=true]
setblock ~36 ~9 ~17 oak_leaves[persistent=true]
setblock ~36 ~9 ~21 oak_leaves[persistent=true]
setblock ~36 ~9 ~22 oak_leaves[persistent=true]
setblock ~36 ~9 ~23 oak_leaves[persistent=true]
setblock ~36 ~10 ~15 oak_leaves[persistent=true]
setblock ~36 ~10 ~16 oak_leaves[persistent=true]
setblock ~36 ~10 ~17 oak_leaves[persistent=true]
setblock ~36 ~10 ~18 oak_leaves[persistent=true]
setblock ~36 ~10 ~19 oak_leaves[persistent=true]
setblock ~36 ~10 ~20 oak_leaves[persistent=true]
setblock ~36 ~10 ~22 oak_leaves[persistent=true]
setblock ~36 ~10 ~23 oak_leaves[persistent=true]
setblock ~36 ~11 ~14 oak_leaves[persistent=true]
setblock ~36 ~11 ~15 oak_leaves[persistent=true]
setblock ~36 ~11 ~16 oak_leaves[persistent=true]
setblock ~36 ~11 ~17 oak_leaves[persistent=true]
setblock ~36 ~11 ~19 oak_leaves[persistent=true]
setblock ~36 ~11 ~20 oak_leaves[persistent=true]
setblock ~36 ~11 ~21 oak_leaves[persistent=true]
setblock ~36 ~11 ~22 oak_leaves[persistent=true]
setblock ~36 ~11 ~23 oak_leaves[persistent=true]
setblock ~36 ~11 ~24 oak_leaves[persistent=true]
setblock ~36 ~12 ~18 oak_leaves[persistent=true]
setblock ~36 ~12 ~19 oak_leaves[persistent=true]
setblock ~36 ~12 ~20 oak_leaves[persistent=true]
setblock ~36 ~12 ~21 oak_leaves[persistent=true]
setblock ~36 ~12 ~22 oak_leaves[persistent=true]
setblock ~36 ~12 ~23 oak_leaves[persistent=true]
setblock ~36 ~12 ~24 oak_leaves[persistent=true]
setblock ~36 ~13 ~15 oak_leaves[persistent=true]
setblock ~36 ~13 ~16 oak_leaves[persistent=true]
setblock ~36 ~13 ~17 oak_leaves[persistent=true]
setblock ~36 ~13 ~18 oak_leaves[persistent=true]
setblock ~36 ~13 ~19 oak_leaves[persistent=true]
setblock ~36 ~13 ~20 oak_leaves[persistent=true]
setblock ~36 ~13 ~21 oak_leaves[persistent=true]
setblock ~36 ~13 ~22 oak_leaves[persistent=true]
setblock ~36 ~13 ~23 oak_leaves[persistent=true]
setblock ~36 ~13 ~25 oak_leaves[persistent=true]
setblock ~36 ~14 ~16 oak_leaves[persistent=true]
setblock ~36 ~14 ~17 oak_leaves[persistent=true]
setblock ~36 ~14 ~18 oak_leaves[persistent=true]
setblock ~36 ~14 ~19 oak_leaves[persistent=true]
setblock ~36 ~14 ~20 oak_leaves[persistent=true]
setblock ~36 ~14 ~21 oak_leaves[persistent=true]
setblock ~37 ~10 ~17 oak_leaves[persistent=true]
setblock ~37 ~10 ~19 oak_leaves[persistent=true]
setblock ~37 ~10 ~20 oak_leaves[persistent=true]
setblock ~37 ~10 ~21 oak_leaves[persistent=true]
setblock ~37 ~10 ~22 oak_leaves[persistent=true]
setblock ~37 ~10 ~23 oak_leaves[persistent=true]
setblock ~37 ~11 ~15 oak_leaves[persistent=true]
setblock ~37 ~11 ~17 oak_leaves[persistent=true]
setblock ~37 ~11 ~18 oak_leaves[persistent=true]
setblock ~37 ~11 ~19 oak_leaves[persistent=true]
setblock ~37 ~11 ~20 oak_leaves[persistent=true]
setblock ~37 ~11 ~21 oak_leaves[persistent=true]
setblock ~37 ~12 ~15 oak_leaves[persistent=true]
setblock ~37 ~12 ~16 oak_leaves[persistent=true]
setblock ~37 ~12 ~17 oak_leaves[persistent=true]
setblock ~37 ~12 ~18 oak_leaves[persistent=true]
setblock ~37 ~12 ~20 oak_leaves[persistent=true]
setblock ~37 ~12 ~21 oak_leaves[persistent=true]
setblock ~37 ~12 ~22 oak_leaves[persistent=true]
setblock ~37 ~12 ~23 oak_leaves[persistent=true]
setblock ~37 ~13 ~17 oak_leaves[persistent=true]
setblock ~37 ~13 ~18 oak_leaves[persistent=true]
setblock ~37 ~13 ~20 oak_leaves[persistent=true]
setblock ~37 ~13 ~21 oak_leaves[persistent=true]
setblock ~37 ~13 ~22 oak_leaves[persistent=true]
setblock ~37 ~14 ~19 oak_leaves[persistent=true]
setblock ~37 ~14 ~22 oak_leaves[persistent=true]
setblock ~38 ~9 ~18 oak_leaves[persistent=true]
setblock ~38 ~10 ~17 oak_leaves[persistent=true]
setblock ~38 ~10 ~18 oak_leaves[persistent=true]
setblock ~38 ~10 ~19 oak_leaves[persistent=true]
setblock ~38 ~10 ~21 oak_leaves[persistent=true]
setblock ~38 ~10 ~23 oak_leaves[persistent=true]
setblock ~38 ~11 ~16 oak_leaves[persistent=true]
setblock ~38 ~11 ~20 oak_leaves[persistent=true]
setblock ~38 ~11 ~21 oak_leaves[persistent=true]
setblock ~38 ~11 ~22 oak_leaves[persistent=true]
setblock ~38 ~12 ~15 oak_leaves[persistent=true]
setblock ~38 ~12 ~16 oak_leaves[persistent=true]
setblock ~38 ~12 ~17 oak_leaves[persistent=true]
setblock ~38 ~12 ~20 oak_leaves[persistent=true]
setblock ~38 ~12 ~22 oak_leaves[persistent=true]
setblock ~38 ~13 ~18 oak_leaves[persistent=true]
setblock ~38 ~13 ~19 oak_leaves[persistent=true]
setblock ~38 ~13 ~22 oak_leaves[persistent=true]
setblock ~38 ~14 ~19 oak_leaves[persistent=true]
setblock ~39 ~11 ~20 oak_leaves[persistent=true]
setblock ~39 ~12 ~17 oak_leaves[persistent=true]
setblock ~39 ~12 ~18 oak_leaves[persistent=true]
setblock ~39 ~12 ~19 oak_leaves[persistent=true]
setblock ~39 ~13 ~20 oak_leaves[persistent=true]
setblock ~40 ~12 ~20 oak_leaves[persistent=true]
setblock ~30 ~ ~30 poppy
setblock ~36 ~ ~31 dandelion
setblock ~28 ~ ~16 azure_bluet
setblock ~39 ~ ~33 cornflower
setblock ~25 ~ ~22 cornflower
setblock ~27 ~ ~32 oak_stairs[facing=north]
setblock ~30 ~ ~32 oak_stairs[facing=north]
setblock ~25 ~ ~25 lantern[hanging=false]
fill ~12 ~ ~24 ~14 ~1 ~26 stone_bricks
setblock ~13 ~ ~25 water
setblock ~13 ~1 ~25 air
fill ~12 ~2 ~24 ~12 ~3 ~24 dark_oak_fence
fill ~14 ~2 ~24 ~14 ~3 ~24 dark_oak_fence
fill ~12 ~2 ~26 ~12 ~3 ~26 dark_oak_fence
fill ~14 ~2 ~26 ~14 ~3 ~26 dark_oak_fence
fill ~11 ~4 ~23 ~15 ~4 ~27 dark_oak_slab[type=bottom]
fill ~12 ~ ~32 ~12 ~ ~32 hay_block
setblock ~12 ~1 ~32 carved_pumpkin[facing=north]
fill ~16 ~ ~32 ~16 ~ ~32 hay_block
setblock ~16 ~1 ~32 carved_pumpkin[facing=north]
fill ~20 ~ ~32 ~20 ~ ~32 hay_block
setblock ~20 ~1 ~32 carved_pumpkin[facing=north]
summon marker ~0 ~ ~52 {Tags:["got_gate"]}
summon marker ~0 ~ ~ {Tags:["got_center"]}
loot insert ~-36 ~ ~21 loot got:armory/swords
loot insert ~-34 ~ ~21 loot got:armory/ranged
loot insert ~-32 ~ ~21 loot got:armory/lannister
loot insert ~-30 ~ ~21 loot got:armory/nights_watch
loot insert ~-28 ~ ~21 loot got:armory/targaryen
loot insert ~-26 ~ ~21 loot got:armory/supplies
