fill ~-44 ~-3 ~-44 ~44 ~-1 ~-42 stone_bricks
fill ~-44 ~ ~-44 ~44 ~1 ~-42 cobblestone
fill ~-44 ~2 ~-44 ~44 ~8 ~-42 stone_bricks
fill ~-44 ~9 ~-44 ~44 ~9 ~-42 polished_andesite
fill ~-44 ~-3 ~42 ~44 ~-1 ~44 stone_bricks
fill ~-44 ~ ~42 ~44 ~1 ~44 cobblestone
fill ~-44 ~2 ~42 ~44 ~8 ~44 stone_bricks
fill ~-44 ~9 ~42 ~44 ~9 ~44 polished_andesite
fill ~-44 ~-3 ~-41 ~-42 ~-1 ~41 stone_bricks
fill ~-44 ~ ~-41 ~-42 ~1 ~41 cobblestone
fill ~-44 ~2 ~-41 ~-42 ~8 ~41 stone_bricks
fill ~-44 ~9 ~-41 ~-42 ~9 ~41 polished_andesite
fill ~42 ~-3 ~-41 ~44 ~-1 ~41 stone_bricks
fill ~42 ~ ~-41 ~44 ~1 ~41 cobblestone
fill ~42 ~2 ~-41 ~44 ~8 ~41 stone_bricks
fill ~42 ~9 ~-41 ~44 ~9 ~41 polished_andesite
fill ~-44 ~10 ~-44 ~44 ~10 ~-44 stone_bricks
fill ~-44 ~10 ~44 ~44 ~10 ~44 stone_bricks
fill ~-44 ~10 ~-44 ~-44 ~10 ~44 stone_bricks
fill ~44 ~10 ~-44 ~44 ~10 ~44 stone_bricks
setblock ~-44 ~11 ~-44 stone_bricks
setblock ~-44 ~11 ~44 stone_bricks
setblock ~-42 ~11 ~-44 stone_bricks
setblock ~-42 ~11 ~44 stone_bricks
setblock ~-40 ~11 ~-44 stone_bricks
setblock ~-40 ~11 ~44 stone_bricks
setblock ~-38 ~11 ~-44 stone_bricks
setblock ~-38 ~11 ~44 stone_bricks
setblock ~-36 ~11 ~-44 stone_bricks
setblock ~-36 ~11 ~44 stone_bricks
setblock ~-34 ~11 ~-44 stone_bricks
setblock ~-34 ~11 ~44 stone_bricks
setblock ~-32 ~11 ~-44 stone_bricks
setblock ~-32 ~11 ~44 stone_bricks
setblock ~-30 ~11 ~-44 stone_bricks
setblock ~-30 ~11 ~44 stone_bricks
setblock ~-28 ~11 ~-44 stone_bricks
setblock ~-28 ~11 ~44 stone_bricks
setblock ~-26 ~11 ~-44 stone_bricks
setblock ~-26 ~11 ~44 stone_bricks
setblock ~-24 ~11 ~-44 stone_bricks
setblock ~-24 ~11 ~44 stone_bricks
setblock ~-22 ~11 ~-44 stone_bricks
setblock ~-22 ~11 ~44 stone_bricks
setblock ~-20 ~11 ~-44 stone_bricks
setblock ~-20 ~11 ~44 stone_bricks
setblock ~-18 ~11 ~-44 stone_bricks
setblock ~-18 ~11 ~44 stone_bricks
setblock ~-16 ~11 ~-44 stone_bricks
setblock ~-16 ~11 ~44 stone_bricks
setblock ~-14 ~11 ~-44 stone_bricks
setblock ~-14 ~11 ~44 stone_bricks
setblock ~-12 ~11 ~-44 stone_bricks
setblock ~-12 ~11 ~44 stone_bricks
setblock ~-10 ~11 ~-44 stone_bricks
setblock ~-10 ~11 ~44 stone_bricks
setblock ~-8 ~11 ~-44 stone_bricks
setblock ~-8 ~11 ~44 stone_bricks
setblock ~-6 ~11 ~-44 stone_bricks
setblock ~-6 ~11 ~44 stone_bricks
setblock ~-4 ~11 ~-44 stone_bricks
setblock ~-4 ~11 ~44 stone_bricks
setblock ~-2 ~11 ~-44 stone_bricks
setblock ~-2 ~11 ~44 stone_bricks
setblock ~ ~11 ~-44 stone_bricks
setblock ~ ~11 ~44 stone_bricks
setblock ~2 ~11 ~-44 stone_bricks
setblock ~2 ~11 ~44 stone_bricks
setblock ~4 ~11 ~-44 stone_bricks
setblock ~4 ~11 ~44 stone_bricks
setblock ~6 ~11 ~-44 stone_bricks
setblock ~6 ~11 ~44 stone_bricks
setblock ~8 ~11 ~-44 stone_bricks
setblock ~8 ~11 ~44 stone_bricks
setblock ~10 ~11 ~-44 stone_bricks
setblock ~10 ~11 ~44 stone_bricks
setblock ~12 ~11 ~-44 stone_bricks
setblock ~12 ~11 ~44 stone_bricks
setblock ~14 ~11 ~-44 stone_bricks
setblock ~14 ~11 ~44 stone_bricks
setblock ~16 ~11 ~-44 stone_bricks
setblock ~16 ~11 ~44 stone_bricks
setblock ~18 ~11 ~-44 stone_bricks
setblock ~18 ~11 ~44 stone_bricks
setblock ~20 ~11 ~-44 stone_bricks
setblock ~20 ~11 ~44 stone_bricks
setblock ~22 ~11 ~-44 stone_bricks
setblock ~22 ~11 ~44 stone_bricks
setblock ~24 ~11 ~-44 stone_bricks
setblock ~24 ~11 ~44 stone_bricks
setblock ~26 ~11 ~-44 stone_bricks
setblock ~26 ~11 ~44 stone_bricks
setblock ~28 ~11 ~-44 stone_bricks
setblock ~28 ~11 ~44 stone_bricks
setblock ~30 ~11 ~-44 stone_bricks
setblock ~30 ~11 ~44 stone_bricks
setblock ~32 ~11 ~-44 stone_bricks
setblock ~32 ~11 ~44 stone_bricks
setblock ~34 ~11 ~-44 stone_bricks
setblock ~34 ~11 ~44 stone_bricks
setblock ~36 ~11 ~-44 stone_bricks
setblock ~36 ~11 ~44 stone_bricks
setblock ~38 ~11 ~-44 stone_bricks
setblock ~38 ~11 ~44 stone_bricks
setblock ~40 ~11 ~-44 stone_bricks
setblock ~40 ~11 ~44 stone_bricks
setblock ~42 ~11 ~-44 stone_bricks
setblock ~42 ~11 ~44 stone_bricks
setblock ~44 ~11 ~-44 stone_bricks
setblock ~44 ~11 ~44 stone_bricks
setblock ~-44 ~11 ~-44 stone_bricks
setblock ~44 ~11 ~-44 stone_bricks
setblock ~-44 ~11 ~-42 stone_bricks
setblock ~44 ~11 ~-42 stone_bricks
setblock ~-44 ~11 ~-40 stone_bricks
setblock ~44 ~11 ~-40 stone_bricks
setblock ~-44 ~11 ~-38 stone_bricks
setblock ~44 ~11 ~-38 stone_bricks
setblock ~-44 ~11 ~-36 stone_bricks
setblock ~44 ~11 ~-36 stone_bricks
setblock ~-44 ~11 ~-34 stone_bricks
setblock ~44 ~11 ~-34 stone_bricks
setblock ~-44 ~11 ~-32 stone_bricks
setblock ~44 ~11 ~-32 stone_bricks
setblock ~-44 ~11 ~-30 stone_bricks
setblock ~44 ~11 ~-30 stone_bricks
setblock ~-44 ~11 ~-28 stone_bricks
setblock ~44 ~11 ~-28 stone_bricks
setblock ~-44 ~11 ~-26 stone_bricks
setblock ~44 ~11 ~-26 stone_bricks
setblock ~-44 ~11 ~-24 stone_bricks
setblock ~44 ~11 ~-24 stone_bricks
setblock ~-44 ~11 ~-22 stone_bricks
setblock ~44 ~11 ~-22 stone_bricks
setblock ~-44 ~11 ~-20 stone_bricks
setblock ~44 ~11 ~-20 stone_bricks
setblock ~-44 ~11 ~-18 stone_bricks
setblock ~44 ~11 ~-18 stone_bricks
setblock ~-44 ~11 ~-16 stone_bricks
setblock ~44 ~11 ~-16 stone_bricks
setblock ~-44 ~11 ~-14 stone_bricks
setblock ~44 ~11 ~-14 stone_bricks
setblock ~-44 ~11 ~-12 stone_bricks
setblock ~44 ~11 ~-12 stone_bricks
setblock ~-44 ~11 ~-10 stone_bricks
setblock ~44 ~11 ~-10 stone_bricks
setblock ~-44 ~11 ~-8 stone_bricks
setblock ~44 ~11 ~-8 stone_bricks
setblock ~-44 ~11 ~-6 stone_bricks
setblock ~44 ~11 ~-6 stone_bricks
setblock ~-44 ~11 ~-4 stone_bricks
setblock ~44 ~11 ~-4 stone_bricks
setblock ~-44 ~11 ~-2 stone_bricks
setblock ~44 ~11 ~-2 stone_bricks
setblock ~-44 ~11 ~ stone_bricks
setblock ~44 ~11 ~ stone_bricks
setblock ~-44 ~11 ~2 stone_bricks
setblock ~44 ~11 ~2 stone_bricks
setblock ~-44 ~11 ~4 stone_bricks
setblock ~44 ~11 ~4 stone_bricks
setblock ~-44 ~11 ~6 stone_bricks
setblock ~44 ~11 ~6 stone_bricks
setblock ~-44 ~11 ~8 stone_bricks
setblock ~44 ~11 ~8 stone_bricks
setblock ~-44 ~11 ~10 stone_bricks
setblock ~44 ~11 ~10 stone_bricks
setblock ~-44 ~11 ~12 stone_bricks
setblock ~44 ~11 ~12 stone_bricks
setblock ~-44 ~11 ~14 stone_bricks
setblock ~44 ~11 ~14 stone_bricks
setblock ~-44 ~11 ~16 stone_bricks
setblock ~44 ~11 ~16 stone_bricks
setblock ~-44 ~11 ~18 stone_bricks
setblock ~44 ~11 ~18 stone_bricks
setblock ~-44 ~11 ~20 stone_bricks
setblock ~44 ~11 ~20 stone_bricks
setblock ~-44 ~11 ~22 stone_bricks
setblock ~44 ~11 ~22 stone_bricks
setblock ~-44 ~11 ~24 stone_bricks
setblock ~44 ~11 ~24 stone_bricks
setblock ~-44 ~11 ~26 stone_bricks
setblock ~44 ~11 ~26 stone_bricks
setblock ~-44 ~11 ~28 stone_bricks
setblock ~44 ~11 ~28 stone_bricks
setblock ~-44 ~11 ~30 stone_bricks
setblock ~44 ~11 ~30 stone_bricks
setblock ~-44 ~11 ~32 stone_bricks
setblock ~44 ~11 ~32 stone_bricks
setblock ~-44 ~11 ~34 stone_bricks
setblock ~44 ~11 ~34 stone_bricks
setblock ~-44 ~11 ~36 stone_bricks
setblock ~44 ~11 ~36 stone_bricks
setblock ~-44 ~11 ~38 stone_bricks
setblock ~44 ~11 ~38 stone_bricks
setblock ~-44 ~11 ~40 stone_bricks
setblock ~44 ~11 ~40 stone_bricks
setblock ~-44 ~11 ~42 stone_bricks
setblock ~44 ~11 ~42 stone_bricks
setblock ~-44 ~11 ~44 stone_bricks
setblock ~44 ~11 ~44 stone_bricks
fill ~-43 ~10 ~-43 ~43 ~11 ~43 air
fill ~-43 ~10 ~-42 ~43 ~10 ~-42 stone_brick_wall
fill ~-43 ~10 ~42 ~43 ~10 ~42 stone_brick_wall
fill ~-42 ~10 ~-43 ~-42 ~10 ~43 stone_brick_wall
fill ~42 ~10 ~-43 ~42 ~10 ~43 stone_brick_wall
fill ~-36 ~4 ~42 ~-36 ~5 ~44 air
setblock ~-36 ~6 ~41 wall_torch[facing=north]
fill ~-36 ~4 ~-44 ~-36 ~5 ~-42 air
setblock ~-36 ~6 ~-41 wall_torch[facing=south]
fill ~-44 ~4 ~-36 ~-42 ~5 ~-36 air
setblock ~-41 ~6 ~-36 wall_torch[facing=east]
fill ~42 ~4 ~-36 ~44 ~5 ~-36 air
setblock ~41 ~6 ~-36 wall_torch[facing=west]
fill ~-28 ~4 ~42 ~-28 ~5 ~44 air
setblock ~-28 ~6 ~41 wall_torch[facing=north]
fill ~-28 ~4 ~-44 ~-28 ~5 ~-42 air
setblock ~-28 ~6 ~-41 wall_torch[facing=south]
fill ~-44 ~4 ~-28 ~-42 ~5 ~-28 air
setblock ~-41 ~6 ~-28 wall_torch[facing=east]
fill ~42 ~4 ~-28 ~44 ~5 ~-28 air
setblock ~41 ~6 ~-28 wall_torch[facing=west]
fill ~-20 ~4 ~42 ~-20 ~5 ~44 air
setblock ~-20 ~6 ~41 wall_torch[facing=north]
fill ~-20 ~4 ~-44 ~-20 ~5 ~-42 air
setblock ~-20 ~6 ~-41 wall_torch[facing=south]
fill ~-44 ~4 ~-20 ~-42 ~5 ~-20 air
setblock ~-41 ~6 ~-20 wall_torch[facing=east]
fill ~42 ~4 ~-20 ~44 ~5 ~-20 air
setblock ~41 ~6 ~-20 wall_torch[facing=west]
fill ~-12 ~4 ~-44 ~-12 ~5 ~-42 air
setblock ~-12 ~6 ~-41 wall_torch[facing=south]
fill ~-44 ~4 ~-12 ~-42 ~5 ~-12 air
setblock ~-41 ~6 ~-12 wall_torch[facing=east]
fill ~42 ~4 ~-12 ~44 ~5 ~-12 air
setblock ~41 ~6 ~-12 wall_torch[facing=west]
fill ~-4 ~4 ~-44 ~-4 ~5 ~-42 air
setblock ~-4 ~6 ~-41 wall_torch[facing=south]
fill ~-44 ~4 ~-4 ~-42 ~5 ~-4 air
setblock ~-41 ~6 ~-4 wall_torch[facing=east]
fill ~42 ~4 ~-4 ~44 ~5 ~-4 air
setblock ~41 ~6 ~-4 wall_torch[facing=west]
fill ~4 ~4 ~-44 ~4 ~5 ~-42 air
setblock ~4 ~6 ~-41 wall_torch[facing=south]
fill ~-44 ~4 ~4 ~-42 ~5 ~4 air
setblock ~-41 ~6 ~4 wall_torch[facing=east]
fill ~42 ~4 ~4 ~44 ~5 ~4 air
setblock ~41 ~6 ~4 wall_torch[facing=west]
fill ~12 ~4 ~-44 ~12 ~5 ~-42 air
setblock ~12 ~6 ~-41 wall_torch[facing=south]
fill ~-44 ~4 ~12 ~-42 ~5 ~12 air
setblock ~-41 ~6 ~12 wall_torch[facing=east]
fill ~42 ~4 ~12 ~44 ~5 ~12 air
setblock ~41 ~6 ~12 wall_torch[facing=west]
fill ~20 ~4 ~42 ~20 ~5 ~44 air
setblock ~20 ~6 ~41 wall_torch[facing=north]
fill ~20 ~4 ~-44 ~20 ~5 ~-42 air
setblock ~20 ~6 ~-41 wall_torch[facing=south]
fill ~-44 ~4 ~20 ~-42 ~5 ~20 air
setblock ~-41 ~6 ~20 wall_torch[facing=east]
fill ~42 ~4 ~20 ~44 ~5 ~20 air
setblock ~41 ~6 ~20 wall_torch[facing=west]
fill ~28 ~4 ~42 ~28 ~5 ~44 air
setblock ~28 ~6 ~41 wall_torch[facing=north]
fill ~28 ~4 ~-44 ~28 ~5 ~-42 air
setblock ~28 ~6 ~-41 wall_torch[facing=south]
fill ~-44 ~4 ~28 ~-42 ~5 ~28 air
setblock ~-41 ~6 ~28 wall_torch[facing=east]
fill ~42 ~4 ~28 ~44 ~5 ~28 air
setblock ~41 ~6 ~28 wall_torch[facing=west]
fill ~36 ~4 ~42 ~36 ~5 ~44 air
setblock ~36 ~6 ~41 wall_torch[facing=north]
fill ~36 ~4 ~-44 ~36 ~5 ~-42 air
setblock ~36 ~6 ~-41 wall_torch[facing=south]
fill ~-44 ~4 ~36 ~-42 ~5 ~36 air
setblock ~-41 ~6 ~36 wall_torch[facing=east]
fill ~42 ~4 ~36 ~44 ~5 ~36 air
setblock ~41 ~6 ~36 wall_torch[facing=west]
setblock ~-36 ~ ~-41 stone_brick_stairs[facing=east]
setblock ~-36 ~ ~-40 stone_brick_stairs[facing=east]
fill ~-35 ~ ~-41 ~-35 ~ ~-41 stone_bricks
setblock ~-35 ~1 ~-41 stone_brick_stairs[facing=east]
fill ~-35 ~ ~-40 ~-35 ~ ~-40 stone_bricks
setblock ~-35 ~1 ~-40 stone_brick_stairs[facing=east]
fill ~-34 ~ ~-41 ~-34 ~1 ~-41 stone_bricks
setblock ~-34 ~2 ~-41 stone_brick_stairs[facing=east]
fill ~-34 ~ ~-40 ~-34 ~1 ~-40 stone_bricks
setblock ~-34 ~2 ~-40 stone_brick_stairs[facing=east]
fill ~-33 ~ ~-41 ~-33 ~2 ~-41 stone_bricks
setblock ~-33 ~3 ~-41 stone_brick_stairs[facing=east]
fill ~-33 ~ ~-40 ~-33 ~2 ~-40 stone_bricks
setblock ~-33 ~3 ~-40 stone_brick_stairs[facing=east]
fill ~-32 ~ ~-41 ~-32 ~3 ~-41 stone_bricks
setblock ~-32 ~4 ~-41 stone_brick_stairs[facing=east]
fill ~-32 ~ ~-40 ~-32 ~3 ~-40 stone_bricks
setblock ~-32 ~4 ~-40 stone_brick_stairs[facing=east]
fill ~-31 ~ ~-41 ~-31 ~4 ~-41 stone_bricks
setblock ~-31 ~5 ~-41 stone_brick_stairs[facing=east]
fill ~-31 ~ ~-40 ~-31 ~4 ~-40 stone_bricks
setblock ~-31 ~5 ~-40 stone_brick_stairs[facing=east]
fill ~-30 ~ ~-41 ~-30 ~5 ~-41 stone_bricks
setblock ~-30 ~6 ~-41 stone_brick_stairs[facing=east]
fill ~-30 ~ ~-40 ~-30 ~5 ~-40 stone_bricks
setblock ~-30 ~6 ~-40 stone_brick_stairs[facing=east]
fill ~-29 ~ ~-41 ~-29 ~6 ~-41 stone_bricks
setblock ~-29 ~7 ~-41 stone_brick_stairs[facing=east]
fill ~-29 ~ ~-40 ~-29 ~6 ~-40 stone_bricks
setblock ~-29 ~7 ~-40 stone_brick_stairs[facing=east]
fill ~-28 ~ ~-41 ~-28 ~7 ~-41 stone_bricks
setblock ~-28 ~8 ~-41 stone_brick_stairs[facing=east]
fill ~-28 ~ ~-40 ~-28 ~7 ~-40 stone_bricks
setblock ~-28 ~8 ~-40 stone_brick_stairs[facing=east]
fill ~-27 ~ ~-41 ~-27 ~8 ~-41 stone_bricks
setblock ~-27 ~9 ~-41 stone_brick_stairs[facing=east]
fill ~-27 ~ ~-40 ~-27 ~8 ~-40 stone_bricks
setblock ~-27 ~9 ~-40 stone_brick_stairs[facing=east]
setblock ~36 ~ ~41 stone_brick_stairs[facing=west]
setblock ~36 ~ ~40 stone_brick_stairs[facing=west]
fill ~35 ~ ~41 ~35 ~ ~41 stone_bricks
setblock ~35 ~1 ~41 stone_brick_stairs[facing=west]
fill ~35 ~ ~40 ~35 ~ ~40 stone_bricks
setblock ~35 ~1 ~40 stone_brick_stairs[facing=west]
fill ~34 ~ ~41 ~34 ~1 ~41 stone_bricks
setblock ~34 ~2 ~41 stone_brick_stairs[facing=west]
fill ~34 ~ ~40 ~34 ~1 ~40 stone_bricks
setblock ~34 ~2 ~40 stone_brick_stairs[facing=west]
fill ~33 ~ ~41 ~33 ~2 ~41 stone_bricks
setblock ~33 ~3 ~41 stone_brick_stairs[facing=west]
fill ~33 ~ ~40 ~33 ~2 ~40 stone_bricks
setblock ~33 ~3 ~40 stone_brick_stairs[facing=west]
fill ~32 ~ ~41 ~32 ~3 ~41 stone_bricks
setblock ~32 ~4 ~41 stone_brick_stairs[facing=west]
fill ~32 ~ ~40 ~32 ~3 ~40 stone_bricks
setblock ~32 ~4 ~40 stone_brick_stairs[facing=west]
fill ~31 ~ ~41 ~31 ~4 ~41 stone_bricks
setblock ~31 ~5 ~41 stone_brick_stairs[facing=west]
fill ~31 ~ ~40 ~31 ~4 ~40 stone_bricks
setblock ~31 ~5 ~40 stone_brick_stairs[facing=west]
fill ~30 ~ ~41 ~30 ~5 ~41 stone_bricks
setblock ~30 ~6 ~41 stone_brick_stairs[facing=west]
fill ~30 ~ ~40 ~30 ~5 ~40 stone_bricks
setblock ~30 ~6 ~40 stone_brick_stairs[facing=west]
fill ~29 ~ ~41 ~29 ~6 ~41 stone_bricks
setblock ~29 ~7 ~41 stone_brick_stairs[facing=west]
fill ~29 ~ ~40 ~29 ~6 ~40 stone_bricks
setblock ~29 ~7 ~40 stone_brick_stairs[facing=west]
fill ~28 ~ ~41 ~28 ~7 ~41 stone_bricks
setblock ~28 ~8 ~41 stone_brick_stairs[facing=west]
fill ~28 ~ ~40 ~28 ~7 ~40 stone_bricks
setblock ~28 ~8 ~40 stone_brick_stairs[facing=west]
fill ~27 ~ ~41 ~27 ~8 ~41 stone_bricks
setblock ~27 ~9 ~41 stone_brick_stairs[facing=west]
fill ~27 ~ ~40 ~27 ~8 ~40 stone_bricks
setblock ~27 ~9 ~40 stone_brick_stairs[facing=west]
setblock ~-41 ~ ~36 stone_brick_stairs[facing=north]
setblock ~-40 ~ ~36 stone_brick_stairs[facing=north]
fill ~-41 ~ ~35 ~-41 ~ ~35 stone_bricks
setblock ~-41 ~1 ~35 stone_brick_stairs[facing=north]
fill ~-40 ~ ~35 ~-40 ~ ~35 stone_bricks
setblock ~-40 ~1 ~35 stone_brick_stairs[facing=north]
fill ~-41 ~ ~34 ~-41 ~1 ~34 stone_bricks
setblock ~-41 ~2 ~34 stone_brick_stairs[facing=north]
fill ~-40 ~ ~34 ~-40 ~1 ~34 stone_bricks
setblock ~-40 ~2 ~34 stone_brick_stairs[facing=north]
fill ~-41 ~ ~33 ~-41 ~2 ~33 stone_bricks
setblock ~-41 ~3 ~33 stone_brick_stairs[facing=north]
fill ~-40 ~ ~33 ~-40 ~2 ~33 stone_bricks
setblock ~-40 ~3 ~33 stone_brick_stairs[facing=north]
fill ~-41 ~ ~32 ~-41 ~3 ~32 stone_bricks
setblock ~-41 ~4 ~32 stone_brick_stairs[facing=north]
fill ~-40 ~ ~32 ~-40 ~3 ~32 stone_bricks
setblock ~-40 ~4 ~32 stone_brick_stairs[facing=north]
fill ~-41 ~ ~31 ~-41 ~4 ~31 stone_bricks
setblock ~-41 ~5 ~31 stone_brick_stairs[facing=north]
fill ~-40 ~ ~31 ~-40 ~4 ~31 stone_bricks
setblock ~-40 ~5 ~31 stone_brick_stairs[facing=north]
fill ~-41 ~ ~30 ~-41 ~5 ~30 stone_bricks
setblock ~-41 ~6 ~30 stone_brick_stairs[facing=north]
fill ~-40 ~ ~30 ~-40 ~5 ~30 stone_bricks
setblock ~-40 ~6 ~30 stone_brick_stairs[facing=north]
fill ~-41 ~ ~29 ~-41 ~6 ~29 stone_bricks
setblock ~-41 ~7 ~29 stone_brick_stairs[facing=north]
fill ~-40 ~ ~29 ~-40 ~6 ~29 stone_bricks
setblock ~-40 ~7 ~29 stone_brick_stairs[facing=north]
fill ~-41 ~ ~28 ~-41 ~7 ~28 stone_bricks
setblock ~-41 ~8 ~28 stone_brick_stairs[facing=north]
fill ~-40 ~ ~28 ~-40 ~7 ~28 stone_bricks
setblock ~-40 ~8 ~28 stone_brick_stairs[facing=north]
fill ~-41 ~ ~27 ~-41 ~8 ~27 stone_bricks
setblock ~-41 ~9 ~27 stone_brick_stairs[facing=north]
fill ~-40 ~ ~27 ~-40 ~8 ~27 stone_bricks
setblock ~-40 ~9 ~27 stone_brick_stairs[facing=north]
setblock ~41 ~ ~-36 stone_brick_stairs[facing=south]
setblock ~40 ~ ~-36 stone_brick_stairs[facing=south]
fill ~41 ~ ~-35 ~41 ~ ~-35 stone_bricks
setblock ~41 ~1 ~-35 stone_brick_stairs[facing=south]
fill ~40 ~ ~-35 ~40 ~ ~-35 stone_bricks
setblock ~40 ~1 ~-35 stone_brick_stairs[facing=south]
fill ~41 ~ ~-34 ~41 ~1 ~-34 stone_bricks
setblock ~41 ~2 ~-34 stone_brick_stairs[facing=south]
fill ~40 ~ ~-34 ~40 ~1 ~-34 stone_bricks
setblock ~40 ~2 ~-34 stone_brick_stairs[facing=south]
fill ~41 ~ ~-33 ~41 ~2 ~-33 stone_bricks
setblock ~41 ~3 ~-33 stone_brick_stairs[facing=south]
fill ~40 ~ ~-33 ~40 ~2 ~-33 stone_bricks
setblock ~40 ~3 ~-33 stone_brick_stairs[facing=south]
fill ~41 ~ ~-32 ~41 ~3 ~-32 stone_bricks
setblock ~41 ~4 ~-32 stone_brick_stairs[facing=south]
fill ~40 ~ ~-32 ~40 ~3 ~-32 stone_bricks
setblock ~40 ~4 ~-32 stone_brick_stairs[facing=south]
fill ~41 ~ ~-31 ~41 ~4 ~-31 stone_bricks
setblock ~41 ~5 ~-31 stone_brick_stairs[facing=south]
fill ~40 ~ ~-31 ~40 ~4 ~-31 stone_bricks
setblock ~40 ~5 ~-31 stone_brick_stairs[facing=south]
fill ~41 ~ ~-30 ~41 ~5 ~-30 stone_bricks
setblock ~41 ~6 ~-30 stone_brick_stairs[facing=south]
fill ~40 ~ ~-30 ~40 ~5 ~-30 stone_bricks
setblock ~40 ~6 ~-30 stone_brick_stairs[facing=south]
fill ~41 ~ ~-29 ~41 ~6 ~-29 stone_bricks
setblock ~41 ~7 ~-29 stone_brick_stairs[facing=south]
fill ~40 ~ ~-29 ~40 ~6 ~-29 stone_bricks
setblock ~40 ~7 ~-29 stone_brick_stairs[facing=south]
fill ~41 ~ ~-28 ~41 ~7 ~-28 stone_bricks
setblock ~41 ~8 ~-28 stone_brick_stairs[facing=south]
fill ~40 ~ ~-28 ~40 ~7 ~-28 stone_bricks
setblock ~40 ~8 ~-28 stone_brick_stairs[facing=south]
fill ~41 ~ ~-27 ~41 ~8 ~-27 stone_bricks
setblock ~41 ~9 ~-27 stone_brick_stairs[facing=south]
fill ~40 ~ ~-27 ~40 ~8 ~-27 stone_bricks
setblock ~40 ~9 ~-27 stone_brick_stairs[facing=south]
