fill ~-27 ~-1 ~-32 ~27 ~-1 ~20 gravel
fill ~-2 ~-1 ~13 ~2 ~-1 ~36 stone_bricks
fill ~-3 ~-1 ~13 ~-3 ~-1 ~36 cobblestone
fill ~3 ~-1 ~13 ~3 ~-1 ~36 cobblestone
fill ~-4 ~ ~16 ~-4 ~1 ~16 stone_brick_wall
setblock ~-4 ~2 ~16 lantern[hanging=false]
fill ~4 ~ ~16 ~4 ~1 ~16 stone_brick_wall
setblock ~4 ~2 ~16 lantern[hanging=false]
fill ~-4 ~ ~22 ~-4 ~1 ~22 stone_brick_wall
setblock ~-4 ~2 ~22 lantern[hanging=false]
fill ~4 ~ ~22 ~4 ~1 ~22 stone_brick_wall
setblock ~4 ~2 ~22 lantern[hanging=false]
fill ~-4 ~ ~28 ~-4 ~1 ~28 stone_brick_wall
setblock ~-4 ~2 ~28 lantern[hanging=false]
fill ~4 ~ ~28 ~4 ~1 ~28 stone_brick_wall
setblock ~4 ~2 ~28 lantern[hanging=false]
fill ~-4 ~ ~34 ~-4 ~1 ~34 stone_brick_wall
setblock ~-4 ~2 ~34 lantern[hanging=false]
fill ~4 ~ ~34 ~4 ~1 ~34 stone_brick_wall
setblock ~4 ~2 ~34 lantern[hanging=false]
fill ~-38 ~-1 ~12 ~-24 ~-1 ~22 stone_bricks
fill ~-38 ~ ~12 ~-24 ~6 ~22 stone_bricks
fill ~-37 ~ ~13 ~-25 ~5 ~21 air
fill ~-37 ~6 ~13 ~-25 ~6 ~21 dark_oak_planks
fill ~-39 ~7 ~11 ~-23 ~7 ~23 dark_oak_planks
fill ~-39 ~8 ~12 ~-23 ~8 ~22 dark_oak_planks
fill ~-39 ~9 ~13 ~-23 ~9 ~21 dark_oak_planks
fill ~-39 ~10 ~14 ~-23 ~10 ~20 dark_oak_planks
fill ~-39 ~11 ~15 ~-23 ~11 ~19 dark_oak_planks
fill ~-39 ~12 ~16 ~-23 ~12 ~18 dark_oak_planks
fill ~-32 ~ ~12 ~-30 ~2 ~12 air
fill ~-32 ~ ~9 ~-30 ~ ~11 stone_bricks
setblock ~-36 ~ ~21 chest[facing=north]
setblock ~-34 ~ ~21 chest[facing=north]
setblock ~-32 ~ ~21 chest[facing=north]
setblock ~-30 ~ ~21 chest[facing=north]
setblock ~-28 ~ ~21 chest[facing=north]
setblock ~-26 ~ ~21 chest[facing=north]
setblock ~-36 ~ ~13 smithing_table
setblock ~-34 ~ ~13 anvil
setblock ~-28 ~ ~13 grindstone[face=floor]
setblock ~-26 ~ ~13 blast_furnace[facing=south]
setblock ~-34 ~5 ~17 lantern[hanging=true]
setblock ~-28 ~5 ~17 lantern[hanging=true]
setblock ~-37 ~3 ~17 wall_torch[facing=east]
setblock ~-25 ~3 ~17 wall_torch[facing=west]
fill ~24 ~-1 ~12 ~38 ~-1 ~36 grass_block
fill ~26 ~-2 ~26 ~31 ~-1 ~30 water
fill ~33 ~ ~18 ~34 ~12 ~19 birch_log
fill ~29 ~9 ~14 ~38 ~11 ~23 red_wool
fill ~31 ~12 ~16 ~36 ~13 ~21 red_wool
fill ~33 ~14 ~18 ~34 ~14 ~19 red_wool
fill ~30 ~8 ~15 ~37 ~8 ~22 red_wool
fill ~33 ~9 ~18 ~34 ~12 ~19 birch_log
setblock ~27 ~ ~32 oak_stairs[facing=north]
setblock ~30 ~ ~32 oak_stairs[facing=north]
setblock ~25 ~ ~25 lantern[hanging=false]
fill ~12 ~ ~24 ~14 ~1 ~26 stone_bricks
setblock ~13 ~ ~25 water
setblock ~13 ~1 ~25 air
fill ~12 ~2 ~24 ~12 ~3 ~24 dark_oak_fence
fill ~14 ~2 ~24 ~14 ~3 ~24 dark_oak_fence
fill ~12 ~2 ~26 ~12 ~3 ~26 dark_oak_fence
fill ~14 ~2 ~26 ~14 ~3 ~26 dark_oak_fence
fill ~11 ~4 ~23 ~15 ~4 ~27 dark_oak_slab[type=bottom]
fill ~12 ~ ~32 ~12 ~ ~32 hay_block
setblock ~12 ~1 ~32 carved_pumpkin[facing=north]
fill ~16 ~ ~32 ~16 ~ ~32 hay_block
setblock ~16 ~1 ~32 carved_pumpkin[facing=north]
fill ~20 ~ ~32 ~20 ~ ~32 hay_block
setblock ~20 ~1 ~32 carved_pumpkin[facing=north]
summon marker ~0 ~ ~52 {Tags:["got_gate"]}
summon marker ~0 ~ ~ {Tags:["got_center"]}
loot insert ~-36 ~ ~21 loot got:armory/swords
loot insert ~-34 ~ ~21 loot got:armory/ranged
loot insert ~-32 ~ ~21 loot got:armory/lannister
loot insert ~-30 ~ ~21 loot got:armory/nights_watch
loot insert ~-28 ~ ~21 loot got:armory/targaryen
loot insert ~-26 ~ ~21 loot got:armory/supplies
