fill ~-27 ~-1 ~-32 ~27 ~-1 ~20 gravel
fill ~-2 ~-1 ~13 ~2 ~-1 ~36 stone_bricks
fill ~-3 ~-1 ~13 ~-3 ~-1 ~36 cobblestone
fill ~3 ~-1 ~13 ~3 ~-1 ~36 cobblestone
fill ~-4 ~ ~16 ~-4 ~1 ~16 stone_brick_wall
setblock ~-4 ~2 ~16 lantern[hanging=false]
fill ~4 ~ ~16 ~4 ~1 ~16 stone_brick_wall
setblock ~4 ~2 ~16 lantern[hanging=false]
fill ~-4 ~ ~22 ~-4 ~1 ~22 stone_brick_wall
setblock ~-4 ~2 ~22 lantern[hanging=false]
fill ~4 ~ ~22 ~4 ~1 ~22 stone_brick_wall
setblock ~4 ~2 ~22 lantern[hanging=false]
fill ~-4 ~ ~28 ~-4 ~1 ~28 stone_brick_wall
setblock ~-4 ~2 ~28 lantern[hanging=false]
fill ~4 ~ ~28 ~4 ~1 ~28 stone_brick_wall
setblock ~4 ~2 ~28 lantern[hanging=false]
fill ~-4 ~ ~34 ~-4 ~1 ~34 stone_brick_wall
setblock ~-4 ~2 ~34 lantern[hanging=false]
fill ~4 ~ ~34 ~4 ~1 ~34 stone_brick_wall
setblock ~4 ~2 ~34 lantern[hanging=false]
fill ~-38 ~-1 ~12 ~-24 ~-1 ~22 stone_bricks
fill ~-38 ~ ~12 ~-24 ~6 ~22 stone_bricks
fill ~-37 ~ ~13 ~-25 ~5 ~21 air
fill ~-37 ~6 ~13 ~-25 ~6 ~21 dark_oak_planks
fill ~-39 ~7 ~11 ~-23 ~7 ~23 dark_oak_planks
fill ~-39 ~8 ~12 ~-23 ~8 ~22 dark_oak_planks
fill ~-39 ~9 ~13 ~-23 ~9 ~21 dark_oak_planks
fill ~-39 ~10 ~14 ~-23 ~10 ~20 dark_oak_planks
fill ~-39 ~11 ~15 ~-23 ~11 ~19 dark_oak_planks
fill ~-39 ~12 ~16 ~-23 ~12 ~18 dark_oak_planks
fill ~-32 ~ ~12 ~-30 ~2 ~12 air
fill ~-32 ~ ~9 ~-30 ~ ~11 stone_bricks
setblock ~-36 ~ ~21 chest[facing=north]
setblock ~-34 ~ ~21 chest[facing=north]
setblock ~-32 ~ ~21 chest[facing=north]
setblock ~-30 ~ ~21 chest[facing=north]
setblock ~-28 ~ ~21 chest[facing=north]
setblock ~-26 ~ ~21 chest[facing=north]
setblock ~-36 ~ ~13 smithing_table
setblock ~-34 ~ ~13 anvil
setblock ~-28 ~ ~13 grindstone[face=floor]
setblock ~-26 ~ ~13 blast_furnace[facing=south]
setblock ~-34 ~5 ~17 lantern[hanging=true]
setblock ~-28 ~5 ~17 lantern[hanging=true]
setblock ~-37 ~3 ~17 wall_torch[facing=east]
setblock ~-25 ~3 ~17 wall_torch[facing=west]
fill ~24 ~-1 ~12 ~38 ~-1 ~36 grass_block
fill ~26 ~-2 ~26 ~31 ~-1 ~30 water
fill ~31 ~ ~17 ~35 ~ ~21 birch_log[axis=y]
fill ~32 ~1 ~18 ~34 ~9 ~20 birch_log[axis=y]
fill ~33 ~10 ~19 ~33 ~13 ~19 birch_log[axis=y]
setblock ~31 ~9 ~19 birch_log[axis=x]
setblock ~30 ~9 ~19 birch_log[axis=x]
setblock ~29 ~10 ~19 birch_log[axis=x]
setblock ~28 ~10 ~19 birch_log[axis=x]
setblock ~35 ~9 ~19 birch_log[axis=x]
setblock ~36 ~9 ~19 birch_log[axis=x]
setblock ~37 ~10 ~19 birch_log[axis=x]
setblock ~38 ~10 ~19 birch_log[axis=x]
setblock ~33 ~9 ~17 birch_log[axis=z]
setblock ~33 ~9 ~16 birch_log[axis=z]
setblock ~33 ~10 ~15 birch_log[axis=z]
setblock ~33 ~10 ~14 birch_log[axis=z]
setblock ~33 ~9 ~21 birch_log[axis=z]
setblock ~33 ~9 ~22 birch_log[axis=z]
setblock ~33 ~10 ~23 birch_log[axis=z]
setblock ~33 ~10 ~24 birch_log[axis=z]
setblock ~32 ~6 ~21 black_wool
setblock ~32 ~5 ~21 red_wool
setblock ~32 ~4 ~21 red_wool
setblock ~34 ~6 ~21 black_wool
setblock ~34 ~5 ~21 red_wool
setblock ~34 ~4 ~21 red_wool
setblock ~33 ~3 ~21 black_wool
setblock ~33 ~2 ~21 black_wool
setblock ~27 ~12 ~20 red_terracotta
setblock ~27 ~13 ~17 red_wool
setblock ~27 ~13 ~18 red_wool
setblock ~27 ~13 ~19 red_terracotta
setblock ~27 ~13 ~20 red_wool
setblock ~27 ~13 ~21 red_terracotta
setblock ~27 ~14 ~18 red_wool
setblock ~27 ~14 ~20 red_terracotta
setblock ~28 ~11 ~18 red_terracotta
setblock ~28 ~12 ~16 red_wool
setblock ~28 ~12 ~18 red_terracotta
setblock ~28 ~12 ~19 red_terracotta
setblock ~28 ~13 ~16 red_wool
setblock ~28 ~13 ~18 red_terracotta
setblock ~28 ~13 ~20 red_wool
setblock ~28 ~13 ~21 red_wool
setblock ~28 ~14 ~15 red_wool
setblock ~28 ~14 ~18 red_wool
setblock ~28 ~14 ~19 red_terracotta
setblock ~28 ~14 ~20 red_wool
setblock ~28 ~14 ~23 red_wool
setblock ~29 ~11 ~15 red_wool
setblock ~29 ~11 ~18 red_wool
setblock ~29 ~12 ~17 red_wool
setblock ~29 ~12 ~18 red_terracotta
setblock ~29 ~12 ~19 red_wool
setblock ~29 ~12 ~22 red_terracotta
setblock ~29 ~12 ~23 red_wool
setblock ~29 ~13 ~15 red_wool
setblock ~29 ~13 ~16 red_terracotta
setblock ~29 ~13 ~18 red_wool
setblock ~29 ~13 ~19 red_terracotta
setblock ~29 ~13 ~20 red_terracotta
setblock ~29 ~13 ~21 red_wool
setblock ~29 ~14 ~18 red_wool
setblock ~29 ~14 ~19 red_terracotta
setblock ~29 ~14 ~20 red_wool
setblock ~29 ~14 ~22 red_wool
setblock ~29 ~15 ~16 red_wool
setblock ~29 ~15 ~19 red_wool
setblock ~29 ~15 ~20 red_wool
setblock ~29 ~15 ~22 red_terracotta
setblock ~30 ~10 ~17 red_wool
setblock ~30 ~10 ~20 red_wool
setblock ~30 ~10 ~21 red_wool
setblock ~30 ~11 ~17 red_terracotta
setblock ~30 ~11 ~21 red_wool
setblock ~30 ~11 ~22 red_terracotta
setblock ~30 ~11 ~23 red_terracotta
setblock ~30 ~12 ~15 red_wool
setblock ~30 ~12 ~16 red_wool
setblock ~30 ~12 ~18 red_wool
setblock ~30 ~12 ~19 red_terracotta
setblock ~30 ~12 ~20 red_wool
setblock ~30 ~12 ~21 red_terracotta
setblock ~30 ~12 ~23 red_wool
setblock ~30 ~13 ~13 red_terracotta
setblock ~30 ~13 ~15 red_wool
setblock ~30 ~13 ~17 red_wool
setblock ~30 ~13 ~18 red_terracotta
setblock ~30 ~13 ~19 red_wool
setblock ~30 ~13 ~20 red_wool
setblock ~30 ~13 ~21 red_wool
setblock ~30 ~13 ~22 red_wool
setblock ~30 ~13 ~23 red_wool
setblock ~30 ~13 ~24 red_wool
setblock ~30 ~14 ~16 red_wool
setblock ~30 ~14 ~17 red_wool
setblock ~30 ~14 ~18 red_terracotta
setblock ~30 ~14 ~19 red_wool
setblock ~30 ~14 ~20 red_terracotta
setblock ~30 ~15 ~18 red_terracotta
setblock ~30 ~15 ~19 red_wool
setblock ~30 ~15 ~23 red_wool
setblock ~30 ~16 ~19 red_wool
setblock ~30 ~16 ~20 red_wool
setblock ~31 ~10 ~18 red_terracotta
setblock ~31 ~10 ~20 red_wool
setblock ~31 ~11 ~16 red_wool
setblock ~31 ~11 ~18 red_wool
setblock ~31 ~11 ~19 red_wool
setblock ~31 ~11 ~20 red_wool
setblock ~31 ~11 ~22 red_wool
setblock ~31 ~12 ~13 red_wool
setblock ~31 ~12 ~14 red_wool
setblock ~31 ~12 ~16 red_terracotta
setblock ~31 ~12 ~18 red_wool
setblock ~31 ~12 ~19 red_wool
setblock ~31 ~12 ~20 red_terracotta
setblock ~31 ~12 ~21 red_wool
setblock ~31 ~12 ~22 red_wool
setblock ~31 ~12 ~23 red_wool
setblock ~31 ~13 ~13 red_terracotta
setblock ~31 ~13 ~15 red_wool
setblock ~31 ~13 ~16 red_wool
setblock ~31 ~13 ~17 red_wool
setblock ~31 ~13 ~18 red_terracotta
setblock ~31 ~13 ~19 red_terracotta
setblock ~31 ~13 ~20 red_wool
setblock ~31 ~13 ~21 red_terracotta
setblock ~31 ~13 ~22 red_terracotta
setblock ~31 ~13 ~23 red_wool
setblock ~31 ~14 ~14 red_terracotta
setblock ~31 ~14 ~15 red_wool
setblock ~31 ~14 ~16 red_wool
setblock ~31 ~14 ~17 red_terracotta
setblock ~31 ~14 ~18 red_wool
setblock ~31 ~14 ~19 red_wool
setblock ~31 ~14 ~20 red_wool
setblock ~31 ~14 ~21 red_wool
setblock ~31 ~14 ~22 red_wool
setblock ~31 ~14 ~23 red_wool
setblock ~31 ~14 ~24 red_terracotta
setblock ~31 ~15 ~17 red_wool
setblock ~31 ~15 ~19 red_wool
setblock ~31 ~15 ~20 red_wool
setblock ~31 ~15 ~21 red_wool
setblock ~31 ~15 ~24 red_terracotta
setblock ~31 ~16 ~19 red_terracotta
setblock ~32 ~10 ~21 red_wool
setblock ~32 ~11 ~17 red_terracotta
setblock ~32 ~11 ~18 red_terracotta
setblock ~32 ~11 ~19 red_terracotta
setblock ~32 ~11 ~20 red_terracotta
setblock ~32 ~11 ~23 red_wool
setblock ~32 ~12 ~13 red_wool
setblock ~32 ~12 ~15 red_wool
setblock ~32 ~12 ~16 red_wool
setblock ~32 ~12 ~17 red_wool
setblock ~32 ~12 ~18 red_wool
setblock ~32 ~12 ~19 red_terracotta
setblock ~32 ~12 ~20 red_terracotta
setblock ~32 ~12 ~21 red_wool
setblock ~32 ~12 ~22 red_wool
setblock ~32 ~12 ~23 red_terracotta
setblock ~32 ~13 ~13 red_wool
setblock ~32 ~13 ~14 red_wool
setblock ~32 ~13 ~15 red_wool
setblock ~32 ~13 ~16 red_wool
setblock ~32 ~13 ~17 red_wool
setblock ~32 ~13 ~18 red_terracotta
setblock ~32 ~13 ~19 red_terracotta
setblock ~32 ~13 ~20 red_wool
setblock ~32 ~13 ~21 red_wool
setblock ~32 ~13 ~22 red_wool
setblock ~32 ~13 ~24 red_wool
setblock ~32 ~14 ~14 red_wool
setblock ~32 ~14 ~15 red_terracotta
setblock ~32 ~14 ~16 red_wool
setblock ~32 ~14 ~17 red_wool
setblock ~32 ~14 ~18 red_wool
setblock ~32 ~14 ~19 red_terracotta
setblock ~32 ~14 ~20 red_wool
setblock ~32 ~14 ~21 red_terracotta
setblock ~32 ~14 ~23 red_terracotta
setblock ~32 ~14 ~25 red_wool
setblock ~32 ~15 ~15 red_terracotta
setblock ~32 ~15 ~16 red_wool
setblock ~32 ~15 ~17 red_wool
setblock ~32 ~15 ~18 red_wool
setblock ~32 ~15 ~19 red_wool
setblock ~32 ~15 ~20 red_wool
setblock ~32 ~15 ~21 red_wool
setblock ~32 ~15 ~22 red_wool
setblock ~32 ~15 ~23 red_wool
setblock ~32 ~16 ~16 red_terracotta
setblock ~32 ~16 ~18 red_terracotta
setblock ~33 ~10 ~19 red_wool
setblock ~33 ~11 ~15 red_terracotta
setblock ~33 ~11 ~16 red_wool
setblock ~33 ~11 ~17 red_wool
setblock ~33 ~11 ~18 red_wool
setblock ~33 ~11 ~19 red_wool
setblock ~33 ~11 ~20 red_terracotta
setblock ~33 ~11 ~21 red_wool
setblock ~33 ~11 ~22 red_wool
setblock ~33 ~11 ~23 red_wool
setblock ~33 ~12 ~14 red_wool
setblock ~33 ~12 ~15 red_wool
setblock ~33 ~12 ~16 red_terracotta
setblock ~33 ~12 ~17 red_wool
setblock ~33 ~12 ~18 red_wool
setblock ~33 ~12 ~19 red_wool
setblock ~33 ~12 ~20 red_wool
setblock ~33 ~12 ~21 red_terracotta
setblock ~33 ~12 ~22 red_wool
setblock ~33 ~12 ~23 red_wool
setblock ~33 ~12 ~24 red_terracotta
setblock ~33 ~13 ~14 red_wool
setblock ~33 ~13 ~16 red_wool
setblock ~33 ~13 ~17 red_terracotta
setblock ~33 ~13 ~18 red_terracotta
setblock ~33 ~13 ~19 red_terracotta
setblock ~33 ~13 ~20 red_wool
setblock ~33 ~13 ~21 red_wool
setblock ~33 ~13 ~22 red_wool
setblock ~33 ~13 ~23 red_wool
setblock ~33 ~13 ~24 red_wool
setblock ~33 ~13 ~25 red_terracotta
setblock ~33 ~14 ~14 red_wool
setblock ~33 ~14 ~15 red_wool
setblock ~33 ~14 ~16 red_wool
setblock ~33 ~14 ~17 red_terracotta
setblock ~33 ~14 ~18 red_wool
setblock ~33 ~14 ~19 red_wool
setblock ~33 ~14 ~20 red_wool
setblock ~33 ~14 ~21 red_wool
setblock ~33 ~14 ~22 red_wool
setblock ~33 ~14 ~23 red_terracotta
setblock ~33 ~14 ~24 red_wool
setblock ~33 ~14 ~25 red_wool
setblock ~33 ~15 ~15 red_wool
setblock ~33 ~15 ~16 red_wool
setblock ~33 ~15 ~17 red_terracotta
setblock ~33 ~15 ~18 red_wool
setblock ~33 ~15 ~19 red_wool
setblock ~33 ~15 ~21 red_wool
setblock ~33 ~15 ~22 red_terracotta
setblock ~33 ~15 ~24 red_wool
setblock ~33 ~16 ~20 red_terracotta
setblock ~33 ~16 ~21 red_wool
setblock ~34 ~10 ~16 red_wool
setblock ~34 ~10 ~18 red_wool
setblock ~34 ~11 ~18 red_terracotta
setblock ~34 ~11 ~19 red_terracotta
setblock ~34 ~11 ~20 red_wool
setblock ~34 ~11 ~21 red_wool
setblock ~34 ~11 ~22 red_wool
setblock ~34 ~11 ~23 red_wool
setblock ~34 ~11 ~24 red_wool
setblock ~34 ~12 ~14 red_wool
setblock ~34 ~12 ~15 red_wool
setblock ~34 ~12 ~16 red_wool
setblock ~34 ~12 ~17 red_wool
setblock ~34 ~12 ~18 red_terracotta
setblock ~34 ~12 ~19 red_wool
setblock ~34 ~12 ~20 red_terracotta
setblock ~34 ~12 ~22 red_wool
setblock ~34 ~12 ~23 red_terracotta
setblock ~34 ~12 ~25 red_wool
setblock ~34 ~13 ~14 red_wool
setblock ~34 ~13 ~16 red_terracotta
setblock ~34 ~13 ~17 red_wool
setblock ~34 ~13 ~18 red_wool
setblock ~34 ~13 ~19 red_wool
setblock ~34 ~13 ~20 red_wool
setblock ~34 ~13 ~21 red_wool
setblock ~34 ~13 ~22 red_terracotta
setblock ~34 ~13 ~23 red_wool
setblock ~34 ~13 ~25 red_terracotta
setblock ~34 ~14 ~13 red_wool
setblock ~34 ~14 ~14 red_wool
setblock ~34 ~14 ~16 red_terracotta
setblock ~34 ~14 ~17 red_wool
setblock ~34 ~14 ~18 red_wool
setblock ~34 ~14 ~19 red_terracotta
setblock ~34 ~14 ~20 red_wool
setblock ~34 ~14 ~21 red_terracotta
setblock ~34 ~14 ~22 red_wool
setblock ~34 ~14 ~24 red_wool
setblock ~34 ~15 ~16 red_terracotta
setblock ~34 ~15 ~17 red_terracotta
setblock ~34 ~15 ~18 red_wool
setblock ~34 ~15 ~19 red_terracotta
setblock ~34 ~15 ~20 red_wool
setblock ~34 ~15 ~21 red_wool
setblock ~34 ~15 ~22 red_wool
setblock ~34 ~15 ~23 red_terracotta
setblock ~34 ~16 ~18 red_wool
setblock ~34 ~16 ~19 red_wool
setblock ~34 ~16 ~21 red_wool
setblock ~35 ~10 ~17 red_terracotta
setblock ~35 ~10 ~18 red_wool
setblock ~35 ~10 ~19 red_wool
setblock ~35 ~10 ~20 red_wool
setblock ~35 ~10 ~21 red_wool
setblock ~35 ~10 ~22 red_wool
setblock ~35 ~11 ~14 red_wool
setblock ~35 ~11 ~15 red_wool
setblock ~35 ~11 ~17 red_wool
setblock ~35 ~11 ~19 red_wool
setblock ~35 ~11 ~20 red_terracotta
setblock ~35 ~11 ~21 red_terracotta
setblock ~35 ~12 ~15 red_terracotta
setblock ~35 ~12 ~16 red_terracotta
setblock ~35 ~12 ~17 red_terracotta
setblock ~35 ~12 ~18 red_wool
setblock ~35 ~12 ~19 red_wool
setblock ~35 ~12 ~20 red_wool
setblock ~35 ~12 ~21 red_wool
setblock ~35 ~12 ~22 red_terracotta
setblock ~35 ~12 ~23 red_wool
setblock ~35 ~13 ~16 red_wool
setblock ~35 ~13 ~17 red_wool
setblock ~35 ~13 ~18 red_wool
setblock ~35 ~13 ~19 red_wool
setblock ~35 ~13 ~20 red_wool
setblock ~35 ~13 ~21 red_wool
setblock ~35 ~13 ~22 red_terracotta
setblock ~35 ~14 ~16 red_wool
setblock ~35 ~14 ~17 red_wool
setblock ~35 ~14 ~18 red_wool
setblock ~35 ~14 ~19 red_terracotta
setblock ~35 ~14 ~20 red_wool
setblock ~35 ~14 ~21 red_terracotta
setblock ~35 ~14 ~22 red_terracotta
setblock ~35 ~14 ~23 red_wool
setblock ~35 ~15 ~14 red_terracotta
setblock ~35 ~15 ~16 red_terracotta
setblock ~35 ~15 ~17 red_wool
setblock ~35 ~15 ~18 red_terracotta
setblock ~35 ~15 ~19 red_wool
setblock ~35 ~15 ~20 red_wool
setblock ~35 ~15 ~21 red_wool
setblock ~35 ~15 ~22 red_wool
setblock ~35 ~16 ~17 red_wool
setblock ~35 ~16 ~18 red_wool
setblock ~35 ~16 ~19 red_wool
setblock ~36 ~10 ~19 red_terracotta
setblock ~36 ~11 ~17 red_wool
setblock ~36 ~11 ~18 red_wool
setblock ~36 ~11 ~19 red_wool
setblock ~36 ~12 ~16 red_terracotta
setblock ~36 ~12 ~17 red_wool
setblock ~36 ~12 ~18 red_wool
setblock ~36 ~12 ~19 red_wool
setblock ~36 ~12 ~20 red_terracotta
setblock ~36 ~12 ~21 red_wool
setblock ~36 ~12 ~22 red_terracotta
setblock ~36 ~12 ~24 red_wool
setblock ~36 ~13 ~14 red_wool
setblock ~36 ~13 ~16 red_wool
setblock ~36 ~13 ~17 red_terracotta
setblock ~36 ~13 ~19 red_terracotta
setblock ~36 ~13 ~21 red_wool
setblock ~36 ~13 ~22 red_terracotta
setblock ~36 ~13 ~23 red_wool
setblock ~36 ~13 ~25 red_wool
setblock ~36 ~14 ~15 red_wool
setblock ~36 ~14 ~17 red_wool
setblock ~36 ~14 ~18 red_wool
setblock ~36 ~14 ~21 red_wool
setblock ~36 ~14 ~22 red_wool
setblock ~36 ~14 ~23 red_wool
setblock ~36 ~14 ~25 red_wool
setblock ~36 ~15 ~17 red_terracotta
setblock ~36 ~15 ~18 red_wool
setblock ~36 ~15 ~19 red_wool
setblock ~37 ~11 ~17 red_wool
setblock ~37 ~11 ~18 red_terracotta
setblock ~37 ~11 ~21 red_terracotta
setblock ~37 ~12 ~15 red_wool
setblock ~37 ~12 ~16 red_terracotta
setblock ~37 ~12 ~17 red_terracotta
setblock ~37 ~12 ~18 red_wool
setblock ~37 ~12 ~19 red_wool
setblock ~37 ~12 ~20 red_terracotta
setblock ~37 ~12 ~21 red_wool
setblock ~37 ~13 ~17 red_wool
setblock ~37 ~13 ~18 red_wool
setblock ~37 ~13 ~19 red_wool
setblock ~37 ~13 ~21 red_wool
setblock ~37 ~13 ~22 red_wool
setblock ~37 ~13 ~23 red_wool
setblock ~37 ~14 ~15 red_wool
setblock ~37 ~14 ~16 red_wool
setblock ~37 ~14 ~18 red_wool
setblock ~37 ~14 ~19 red_wool
setblock ~37 ~14 ~20 red_wool
setblock ~37 ~14 ~23 red_terracotta
setblock ~37 ~15 ~17 red_wool
setblock ~37 ~15 ~18 red_terracotta
setblock ~37 ~15 ~19 red_wool
setblock ~37 ~15 ~20 red_terracotta
setblock ~37 ~15 ~21 red_terracotta
setblock ~38 ~11 ~18 red_wool
setblock ~38 ~12 ~16 red_wool
setblock ~38 ~12 ~17 red_wool
setblock ~38 ~12 ~20 red_wool
setblock ~38 ~12 ~21 red_wool
setblock ~38 ~13 ~17 red_terracotta
setblock ~38 ~13 ~18 red_wool
setblock ~38 ~13 ~19 red_terracotta
setblock ~38 ~13 ~21 red_wool
setblock ~38 ~13 ~23 red_wool
setblock ~38 ~14 ~18 red_wool
setblock ~38 ~14 ~20 red_wool
setblock ~39 ~12 ~20 red_terracotta
setblock ~39 ~13 ~21 red_wool
setblock ~36 ~9 ~24 red_wool
setblock ~32 ~9 ~16 red_wool
setblock ~32 ~8 ~16 red_wool
setblock ~28 ~9 ~22 red_wool
setblock ~28 ~8 ~22 red_wool
setblock ~28 ~7 ~22 red_wool
setblock ~29 ~9 ~23 red_wool
setblock ~29 ~8 ~23 red_wool
setblock ~29 ~7 ~23 red_wool
setblock ~27 ~9 ~21 red_wool
setblock ~27 ~8 ~21 red_wool
setblock ~27 ~7 ~21 red_wool
setblock ~32 ~9 ~14 red_wool
setblock ~32 ~8 ~14 red_wool
setblock ~32 ~7 ~14 red_wool
setblock ~35 ~9 ~13 red_wool
setblock ~35 ~8 ~13 red_wool
setblock ~35 ~7 ~13 red_wool
setblock ~33 ~9 ~18 red_wool
setblock ~33 ~8 ~18 red_wool
setblock ~33 ~7 ~18 red_wool
setblock ~33 ~9 ~22 red_wool
setblock ~33 ~8 ~22 red_wool
setblock ~29 ~9 ~14 red_wool
setblock ~29 ~8 ~14 red_wool
setblock ~29 ~7 ~14 red_wool
setblock ~37 ~9 ~22 red_wool
setblock ~37 ~8 ~22 red_wool
setblock ~37 ~7 ~22 red_wool
setblock ~31 ~9 ~14 red_wool
setblock ~30 ~9 ~24 red_wool
setblock ~30 ~8 ~24 red_wool
setblock ~30 ~7 ~24 red_wool
setblock ~27 ~ ~32 oak_stairs[facing=north]
setblock ~30 ~ ~32 oak_stairs[facing=north]
setblock ~25 ~ ~25 lantern[hanging=false]
fill ~12 ~ ~24 ~14 ~1 ~26 stone_bricks
setblock ~13 ~ ~25 water
setblock ~13 ~1 ~25 air
fill ~12 ~2 ~24 ~12 ~3 ~24 dark_oak_fence
fill ~14 ~2 ~24 ~14 ~3 ~24 dark_oak_fence
fill ~12 ~2 ~26 ~12 ~3 ~26 dark_oak_fence
fill ~14 ~2 ~26 ~14 ~3 ~26 dark_oak_fence
fill ~11 ~4 ~23 ~15 ~4 ~27 dark_oak_slab[type=bottom]
fill ~12 ~ ~32 ~12 ~ ~32 hay_block
setblock ~12 ~1 ~32 carved_pumpkin[facing=north]
fill ~16 ~ ~32 ~16 ~ ~32 hay_block
setblock ~16 ~1 ~32 carved_pumpkin[facing=north]
fill ~20 ~ ~32 ~20 ~ ~32 hay_block
setblock ~20 ~1 ~32 carved_pumpkin[facing=north]
summon marker ~0 ~ ~52 {Tags:["got_gate"]}
summon marker ~0 ~ ~ {Tags:["got_center"]}
loot insert ~-36 ~ ~21 loot got:armory/swords
loot insert ~-34 ~ ~21 loot got:armory/ranged
loot insert ~-32 ~ ~21 loot got:armory/lannister
loot insert ~-30 ~ ~21 loot got:armory/nights_watch
loot insert ~-28 ~ ~21 loot got:armory/targaryen
loot insert ~-26 ~ ~21 loot got:armory/supplies
